Workbook

Sheet Centralizator Medii
A1: COLEGIUL 'EMIL NEGRUȚIU' TURDA — CENTRALIZATOR MEDII & SITUAȚIE ȘCOLARĂ
A2: CLASA a IX-a TH — Domeniul Turism și Alimentație (Lucrător Hotelier) | An școlar 2026-2027 | Centralizare medii generale, purtare și statut școlar
B4: TOTAL ELEVI | E4: ELEVI PROMOVATI | H4: MEDIA CLASEI | K4: ELEVI CORIGENȚI
B5: =COUNTA(B9:B40) -> 32 | E5: =COUNTIF(I9:I40, "Promovat") -> 0 | H5: =IFERROR(ROUND(AVERAGE(G9:G40), 2), "") | K5: =COUNTIF(I9:I40, "Corigent / Repetent") -> 0
A8: NR. | B8: NUME SI PRENUME | C8: NR. MATR. | D8: RM / PG | E8: MEDIA CG | F8: MEDIA MODULE | G8: MEDIA GENERALĂ | H8: NOTĂ PURTARE | I8: STATUT ȘCOLAR | J8: TOTAL ABSENȚE | K8: RANG | L8: CLASAMENT / PREMIU
A9: 1 | B9: ALBAC V. ALEXANDRU ANDREI | C9: 13 | D9: 126/76 | E9: ='Cultură Generală'!E9 | F9: ='Module Tehnologice'!E9 | G9: =IF(AND(E9="", F9=""), "", IFERROR(ROUND(AVERAGE(E9, F9), 2), "")) | H9: ='Absențe & Purtare'!H9 -> 10 | I9: =IF(AND(E9="", F9=""), "", IF(OR(E9<5, F9<5, H9<5), "Corigent / Repetent", "Promovat")) | J9: ='Absențe & Purtare'!G9 | K9: =IF(G9="", "", RANK(G9, $G$9:$G$40)) | L9: =IF(K9="", "", IF(K9=1, "Premiul I", IF(K9=2, "Premiul II", IF(K9=3, "Premiul III", IF(K9<=7, "Mențiune", "Membru")))))
A10: 2 | B10: BARA D. ADRIAN DANIEL | C10: 14 | D10: 126/77 | E10: ='Cultură Generală'!E10 | F10: ='Module Tehnologice'!E10 | G10: =IF(AND(E10="", F10=""), "", IFERROR(ROUND(AVERAGE(E10, F10), 2), "")) | H10: ='Absențe & Purtare'!H10 -> 10 | I10: =IF(AND(E10="", F10=""), "", IF(OR(E10<5, F10<5, H10<5), "Corigent / Repetent", "Promovat")) | J10: ='Absențe & Purtare'!G10 | K10: =IF(G10="", "", RANK(G10, $G$9:$G$40)) | L10: =IF(K10="", "", IF(K10=1, "Premiul I", IF(K10=2, "Premiul II", IF(K10=3, "Premiul III", IF(K10<=7, "Mențiune", "Membru")))))
A11: 3 | B11: BUDACĂ I. MARIA MADALINA | C11: 15 | D11: 126/78 | E11: ='Cultură Generală'!E11 | F11: ='Module Tehnologice'!E11 | G11: =IF(AND(E11="", F11=""), "", IFERROR(ROUND(AVERAGE(E11, F11), 2), "")) | H11: ='Absențe & Purtare'!H11 -> 10 | I11: =IF(AND(E11="", F11=""), "", IF(OR(E11<5, F11<5, H11<5), "Corigent / Repetent", "Promovat")) | J11: ='Absențe & Purtare'!G11 | K11: =IF(G11="", "", RANK(G11, $G$9:$G$40)) | L11: =IF(K11="", "", IF(K11=1, "Premiul I", IF(K11=2, "Premiul II", IF(K11=3, "Premiul III", IF(K11<=7, "Mențiune", "Membru")))))
A12: 4 | B12: BUDULĂU I.M. VLAD IOAN | C12: 16 | D12: 126/79 | E12: ='Cultură Generală'!E12 | F12: ='Module Tehnologice'!E12 | G12: =IF(AND(E12="", F12=""), "", IFERROR(ROUND(AVERAGE(E12, F12), 2), "")) | H12: ='Absențe & Purtare'!H12 -> 10 | I12: =IF(AND(E12="", F12=""), "", IF(OR(E12<5, F12<5, H12<5), "Corigent / Repetent", "Promovat")) | J12: ='Absențe & Purtare'!G12 | K12: =IF(G12="", "", RANK(G12, $G$9:$G$40)) | L12: =IF(K12="", "", IF(K12=1, "Premiul I", IF(K12=2, "Premiul II", IF(K12=3, "Premiul III", IF(K12<=7, "Mențiune", "Membru")))))
A13: 5 | B13: CHESZOVAN D.E. IRINA JULIETA | C13: 17 | D13: 126/80 | E13: ='Cultură Generală'!E13 | F13: ='Module Tehnologice'!E13 | G13: =IF(AND(E13="", F13=""), "", IFERROR(ROUND(AVERAGE(E13, F13), 2), "")) | H13: ='Absențe & Purtare'!H13 -> 10 | I13: =IF(AND(E13="", F13=""), "", IF(OR(E13<5, F13<5, H13<5), "Corigent / Repetent", "Promovat")) | J13: ='Absențe & Purtare'!G13 | K13: =IF(G13="", "", RANK(G13, $G$9:$G$40)) | L13: =IF(K13="", "", IF(K13=1, "Premiul I", IF(K13=2, "Premiul II", IF(K13=3, "Premiul III", IF(K13<=7, "Mențiune", "Membru")))))
A14: 6 | B14: CIURCUI V. DIANA | C14: 18 | D14: 126/81 | E14: ='Cultură Generală'!E14 | F14: ='Module Tehnologice'!E14 | G14: =IF(AND(E14="", F14=""), "", IFERROR(ROUND(AVERAGE(E14, F14), 2), "")) | H14: ='Absențe & Purtare'!H14 -> 10 | I14: =IF(AND(E14="", F14=""), "", IF(OR(E14<5, F14<5, H14<5), "Corigent / Repetent", "Promovat")) | J14: ='Absențe & Purtare'!G14 | K14: =IF(G14="", "", RANK(G14, $G$9:$G$40)) | L14: =IF(K14="", "", IF(K14=1, "Premiul I", IF(K14=2, "Premiul II", IF(K14=3, "Premiul III", IF(K14<=7, "Mențiune", "Membru")))))
A15: 7 | B15: CORDIȘ M.C. EDUARD IONUȚ | C15: 19 | D15: 126/82 | E15: ='Cultură Generală'!E15 | F15: ='Module Tehnologice'!E15 | G15: =IF(AND(E15="", F15=""), "", IFERROR(ROUND(AVERAGE(E15, F15), 2), "")) | H15: ='Absențe & Purtare'!H15 -> 10 | I15: =IF(AND(E15="", F15=""), "", IF(OR(E15<5, F15<5, H15<5), "Corigent / Repetent", "Promovat")) | J15: ='Absențe & Purtare'!G15 | K15: =IF(G15="", "", RANK(G15, $G$9:$G$40)) | L15: =IF(K15="", "", IF(K15=1, "Premiul I", IF(K15=2, "Premiul II", IF(K15=3, "Premiul III", IF(K15<=7, "Mențiune", "Membru")))))
A16: 8 | B16: DEMETER D.C. DENIS RĂZVAN | C16: 20 | D16: 126/83 | E16: ='Cultură Generală'!E16 | F16: ='Module Tehnologice'!E16 | G16: =IF(AND(E16="", F16=""), "", IFERROR(ROUND(AVERAGE(E16, F16), 2), "")) | H16: ='Absențe & Purtare'!H16 -> 10 | I16: =IF(AND(E16="", F16=""), "", IF(OR(E16<5, F16<5, H16<5), "Corigent / Repetent", "Promovat")) | J16: ='Absențe & Purtare'!G16 | K16: =IF(G16="", "", RANK(G16, $G$9:$G$40)) | L16: =IF(K16="", "", IF(K16=1, "Premiul I", IF(K16=2, "Premiul II", IF(K16=3, "Premiul III", IF(K16<=7, "Mențiune", "Membru")))))
A17: 9 | B17: FERENCZI E.C. MEDEA MARICARMEN | C17: 21 | D17: 126/84 | E17: ='Cultură Generală'!E17 | F17: ='Module Tehnologice'!E17 | G17: =IF(AND(E17="", F17=""), "", IFERROR(ROUND(AVERAGE(E17, F17), 2), "")) | H17: ='Absențe & Purtare'!H17 -> 10 | I17: =IF(AND(E17="", F17=""), "", IF(OR(E17<5, F17<5, H17<5), "Corigent / Repetent", "Promovat")) | J17: ='Absențe & Purtare'!G17 | K17: =IF(G17="", "", RANK(G17, $G$9:$G$40)) | L17: =IF(K17="", "", IF(K17=1, "Premiul I", IF(K17=2, "Premiul II", IF(K17=3, "Premiul III", IF(K17<=7, "Mențiune", "Membru")))))
A18: 10 | B18: FLOREA V. FLAVIU CRISTIAN | C18: 22 | D18: 126/85 | E18: ='Cultură Generală'!E18 | F18: ='Module Tehnologice'!E18 | G18: =IF(AND(E18="", F18=""), "", IFERROR(ROUND(AVERAGE(E18, F18), 2), "")) | H18: ='Absențe & Purtare'!H18 -> 10 | I18: =IF(AND(E18="", F18=""), "", IF(OR(E18<5, F18<5, H18<5), "Corigent / Repetent", "Promovat")) | J18: ='Absențe & Purtare'!G18 | K18: =IF(G18="", "", RANK(G18, $G$9:$G$40)) | L18: =IF(K18="", "", IF(K18=1, "Premiul I", IF(K18=2, "Premiul II", IF(K18=3, "Premiul III", IF(K18<=7, "Mențiune", "Membru")))))
A19: 11 | B19: GHERMAN M.I. DAVID MARIUS | C19: 23 | D19: 126/86 | E19: ='Cultură Generală'!E19 | F19: ='Module Tehnologice'!E19 | G19: =IF(AND(E19="", F19=""), "", IFERROR(ROUND(AVERAGE(E19, F19), 2), "")) | H19: ='Absențe & Purtare'!H19 -> 10 | I19: =IF(AND(E19="", F19=""), "", IF(OR(E19<5, F19<5, H19<5), "Corigent / Repetent", "Promovat")) | J19: ='Absențe & Purtare'!G19 | K19: =IF(G19="", "", RANK(G19, $G$9:$G$40)) | L19: =IF(K19="", "", IF(K19=1, "Premiul I", IF(K19=2, "Premiul II", IF(K19=3, "Premiul III", IF(K19<=7, "Mențiune", "Membru")))))
A20: 12 | B20: LOBONȚ M. MIHNEA | C20: 24 | D20: 126/87 | E20: ='Cultură Generală'!E20 | F20: ='Module Tehnologice'!E20 | G20: =IF(AND(E20="", F20=""), "", IFERROR(ROUND(AVERAGE(E20, F20), 2), "")) | H20: ='Absențe & Purtare'!H20 -> 10 | I20: =IF(AND(E20="", F20=""), "", IF(OR(E20<5, F20<5, H20<5), "Corigent / Repetent", "Promovat")) | J20: ='Absențe & Purtare'!G20 | K20: =IF(G20="", "", RANK(G20, $G$9:$G$40)) | L20: =IF(K20="", "", IF(K20=1, "Premiul I", IF(K20=2, "Premiul II", IF(K20=3, "Premiul III", IF(K20<=7, "Mențiune", "Membru")))))
... A40: 32 | B40: VRÎNCIANU M.G. DELIA MARIA | C40: 44 | D40: 128/6 | E40: ='Cultură Generală'!E40 | F40: ='Module Tehnologice'!E40 | G40: =IF(AND(E40="", F40=""), "", IFERROR(ROUND(AVERAGE(E40, F40), 2), "")) | H40: ='Absențe & Purtare'!H40 -> 10 | I40: =IF(AND(E40="", F40=""), "", IF(OR(E40<5, F40<5, H40<5), "Corigent / Repetent", "Promovat")) | J40: ='Absențe & Purtare'!G40 | K40: =IF(G40="", "", RANK(G40, $G$9:$G$40)) | L40: =IF(K40="", "", IF(K40=1, "Premiul I", IF(K40=2, "Premiul II", IF(K40=3, "Premiul III", IF(K40<=7, "Mențiune", "Membru")))))

Sheet Cultură Generală
A1: COLEGIUL 'EMIL NEGRUȚIU' TURDA — DISCIPLINE CULTURĂ GENERALĂ (TRUNCHI COMUN)
A2: CLASA a IX-a TH — Domeniul Turism și Alimentație (Lucrător Hotelier) | An școlar 2026-2027 | Note (N1..N5), Date Note (D1..D5) și Date Absențe (21.09, 25.09m) cu numărare automată per disciplină
A6: NR. | B6: NUME SI PRENUME | C6: NR. MATR. | D6: RM/PG | E6: MEDIA GEN. CLASĂ | F6: TOT. ABS. NEM | G6: TOT. ABS. MOT | H6: Limba și literatura română | AC6: Limba engleză (L1) | AX6: Limba franceză (L2) | BS6: Matematică | CN6: Fizică | DI6: Chimie | ED6: Biologie | EY6: Istorie | FT6: Geografie | GO6: Logică, argumentare și comunicare | HJ6: Informatică / TIC | IE6: Educație fizică | IZ6: Religie | JU6: Arte vizuale și educație plastică
H7: N1 | I7: D1 | J7: N2 | K7: D2 | L7: N3 | M7: D3 | N7: N4 | O7: D4 | P7: N5 | Q7: D5 | R7: MEDIE | S7: A1 | T7: A2 | U7: A3 | V7: A4 | W7: A5 | X7: A6 | Y7: A7 | Z7: A8 | AA7: ABS.MOT | AB7: ABS.NEM | AC7: N1 | AD7: D1 | AE7: N2 | AF7: D2 | AG7: N3 | AH7: D3 | AI7: N4 | AJ7: D4 | AK7: N5 | AL7: D5 | AM7: MEDIE | AN7: A1 | AO7: A2 | AP7: A3 | AQ7: A4 | AR7: A5 | AS7: A6 | AT7: A7 | AU7: A8 | AV7: ABS.MOT | AW7: ABS.NEM | AX7: N1 | AY7: D1 | AZ7: N2 | BA7: D2 | BB7: N3 | BC7: D3 | BD7: N4 | BE7: D4 | BF7: N5 | BG7: D5 | BH7: MEDIE | BI7: A1 | BJ7: A2 | BK7: A3 | BL7: A4 | BM7: A5 | BN7: A6 | BO7: A7 | BP7: A8 | BQ7: ABS.MOT | BR7: ABS.NEM | BS7: N1 | BT7: D1 | BU7: N2 | BV7: D2 | BW7: N3 | BX7: D3 | BY7: N4 | BZ7: D4 | CA7: N5 | CB7: D5 | CC7: MEDIE | CD7: A1 | CE7: A2 | CF7: A3 | CG7: A4 | CH7: A5 | CI7: A6 | CJ7: A7 | CK7: A8 | CL7: ABS.MOT | CM7: ABS.NEM | CN7: N1 | CO7: D1 | CP7: N2 | CQ7: D2 | CR7: N3 | CS7: D3 | CT7: N4 | CU7: D4 | CV7: N5 | CW7: D5 | CX7: MEDIE | CY7: A1 | CZ7: A2 | DA7: A3 | DB7: A4 | DC7: A5 | DD7: A6 | DE7: A7 | DF7: A8 | DG7: ABS.MOT | DH7: ABS.NEM | DI7: N1 | DJ7: D1 | DK7: N2 | DL7: D2 | DM7: N3 | DN7: D3 | DO7: N4 | DP7: D4 | DQ7: N5 | DR7: D5 | DS7: MEDIE | DT7: A1 | DU7: A2 | DV7: A3 | DW7: A4 | DX7: A5 | DY7: A6 | DZ7: A7 | EA7: A8 | EB7: ABS.MOT | EC7: ABS.NEM | ED7: N1 | EE7: D1 | EF7: N2 | EG7: D2 | EH7: N3 | EI7: D3 | EJ7: N4 | EK7: D4 | EL7: N5 | EM7: D5 | EN7: MEDIE | EO7: A1 | EP7: A2 | EQ7: A3 | ER7: A4 | ES7: A5 | ET7: A6 | EU7: A7 | EV7: A8 | EW7: ABS.MOT | EX7: ABS.NEM | EY7: N1 | EZ7: D1 | FA7: N2 | FB7: D2 | FC7: N3 | FD7: D3 | FE7: N4 | FF7: D4 | FG7: N5 | FH7: D5 | FI7: MEDIE | FJ7: A1 | FK7: A2 | FL7: A3 | FM7: A4 | FN7: A5 | FO7: A6 | FP7: A7 | FQ7: A8 | FR7: ABS.MOT | FS7: ABS.NEM | FT7: N1 | FU7: D1 | FV7: N2 | FW7: D2 | FX7: N3 | FY7: D3 | FZ7: N4 | GA7: D4 | GB7: N5 | GC7: D5 | GD7: MEDIE | GE7: A1 | GF7: A2 | GG7: A3 | GH7: A4 | GI7: A5 | GJ7: A6 | GK7: A7 | GL7: A8 | GM7: ABS.MOT | GN7: ABS.NEM | GO7: N1 | GP7: D1 | GQ7: N2 | GR7: D2 | GS7: N3 | GT7: D3 | GU7: N4 | GV7: D4 | GW7: N5 | GX7: D5 | GY7: MEDIE | GZ7: A1 | HA7: A2 | HB7: A3 | HC7: A4 | HD7: A5 | HE7: A6 | HF7: A7 | HG7: A8 | HH7: ABS.MOT | HI7: ABS.NEM | HJ7: N1 | HK7: D1 | HL7: N2 | HM7: D2 | HN7: N3 | HO7: D3 | HP7: N4 | HQ7: D4 | HR7: N5 | HS7: D5 | HT7: MEDIE | HU7: A1 | HV7: A2 | HW7: A3 | HX7: A4 | HY7: A5 | HZ7: A6 | IA7: A7 | IB7: A8 | IC7: ABS.MOT | ID7: ABS.NEM | IE7: N1 | IF7: D1 | IG7: N2 | IH7: D2 | II7: N3 | IJ7: D3 | IK7: N4 | IL7: D4 | IM7: N5 | IN7: D5 | IO7: MEDIE | IP7: A1 | IQ7: A2 | IR7: A3 | IS7: A4 | IT7: A5 | IU7: A6 | IV7: A7 | IW7: A8 | IX7: ABS.MOT | IY7: ABS.NEM | IZ7: N1 | JA7: D1 | JB7: N2 | JC7: D2 | JD7: N3 | JE7: D3 | JF7: N4 | JG7: D4 | JH7: N5 | JI7: D5 | JJ7: MEDIE | JK7: A1 | JL7: A2 | JM7: A3 | JN7: A4 | JO7: A5 | JP7: A6 | JQ7: A7 | JR7: A8 | JS7: ABS.MOT | JT7: ABS.NEM | JU7: N1 | JV7: D1 | JW7: N2 | JX7: D2 | JY7: N3 | JZ7: D3 | KA7: N4 | KB7: D4 | KC7: N5 | KD7: D5 | KE7: MEDIE | KF7: A1 | KG7: A2 | KH7: A3 | KI7: A4 | KJ7: A5 | KK7: A6 | KL7: A7 | KM7: A8 | KN7: ABS.MOT | KO7: ABS.NEM
A9: 1 | B9: ALBAC V. ALEXANDRU ANDREI | C9: 13 | D9: 126/76 | E9: =IFERROR(ROUND(AVERAGE(R9,AM9,BH9,CC9,CX9,DS9,EN9,FI9,GD9,GY9,HT9,IO9,JJ9,KE9), 2), "") | F9: =IF(SUM(AB9,AW9,BR9,CM9,DH9,EC9,EX9,FS9,GN9,HI9,ID9,IY9,JT9,KO9)=0, "", SUM(AB9,AW9,BR9,CM9,DH9,EC9,EX9,FS9,GN9,HI9,ID9,IY9,JT9,KO9)) | G9: =IF(SUM(AA9,AV9,BQ9,CL9,DG9,EB9,EW9,FR9,GM9,HH9,IC9,IX9,JS9,KN9)=0, "", SUM(AA9,AV9,BQ9,CL9,DG9,EB9,EW9,FR9,GM9,HH9,IC9,IX9,JS9,KN9)) | R9: =IFERROR(ROUND(AVERAGE(H9,J9,L9,N9,P9), 2), "") | AA9: =IF(COUNTA(S9:Z9)=0, "", SUMPRODUCT(--ISNUMBER(SEARCH("m", S9:Z9)))) | AB9: =IF(COUNTA(S9:Z9)=0, "", COUNTA(S9:Z9) - SUMPRODUCT(--ISNUMBER(SEARCH("m", S9:Z9)))) | AM9: =IFERROR(ROUND(AVERAGE(AC9,AE9,AG9,AI9,AK9), 2), "") | AV9: =IF(COUNTA(AN9:AU9)=0, "", SUMPRODUCT(--ISNUMBER(SEARCH("m", AN9:AU9)))) | AW9: =IF(COUNTA(AN9:AU9)=0, "", COUNTA(AN9:AU9) - SUMPRODUCT(--ISNUMBER(SEARCH("m", AN9:AU9)))) | BH9: =IFERROR(ROUND(AVERAGE(AX9,AZ9,BB9,BD9,BF9), 2), "") | BQ9: =IF(COUNTA(BI9:BP9)=0, "", SUMPRODUCT(--ISNUMBER(SEARCH("m", BI9:BP9)))) | BR9: =IF(COUNTA(BI9:BP9)=0, "", COUNTA(BI9:BP9) - SUMPRODUCT(--ISNUMBER(SEARCH("m", BI9:BP9)))) | CC9: =IFERROR(ROUND(AVERAGE(BS9,BU9,BW9,BY9,CA9), 2), "") | CL9: =IF(COUNTA(CD9:CK9)=0, "", SUMPRODUCT(--ISNUMBER(SEARCH("m", CD9:CK9)))) | CM9: =IF(COUNTA(CD9:CK9)=0, "", COUNTA(CD9:CK9) - SUMPRODUCT(--ISNUMBER(SEARCH("m", CD9:CK9)))) | CX9: =IFERROR(ROUND(AVERAGE(CN9,CP9,CR9,CT9,CV9), 2), "") | DG9: =IF(COUNTA(CY9:DF9)=0, "", SUMPRODUCT(--ISNUMBER(SEARCH("m", CY9:DF9)))) | DH9: =IF(COUNTA(CY9:DF9)=0, "", COUNTA(CY9:DF9) - SUMPRODUCT(--ISNUMBER(SEARCH("m", CY9:DF9)))) | DS9: =IFERROR(ROUND(AVERAGE(DI9,DK9,DM9,DO9,DQ9), 2), "") | EB9: =IF(COUNTA(DT9:EA9)=0, "", SUMPRODUCT(--ISNUMBER(SEARCH("m", DT9:EA9)))) | EC9: =IF(COUNTA(DT9:EA9)=0, "", COUNTA(DT9:EA9) - SUMPRODUCT(--ISNUMBER(SEARCH("m", DT9:EA9)))) | EN9: =IFERROR(ROUND(AVERAGE(ED9,EF9,EH9,EJ9,EL9), 2), "") | EW9: =IF(COUNTA(EO9:EV9)=0, "", SUMPRODUCT(--ISNUMBER(SEARCH("m", EO9:EV9)))) | EX9: =IF(COUNTA(EO9:EV9)=0, "", COUNTA(EO9:EV9) - SUMPRODUCT(--ISNUMBER(SEARCH("m", EO9:EV9)))) | FI9: =IFERROR(ROUND(AVERAGE(EY9,FA9,FC9,FE9,FG9), 2), "") | FR9: =IF(COUNTA(FJ9:FQ9)=0, "", SUMPRODUCT(--ISNUMBER(SEARCH("m", FJ9:FQ9)))) | FS9: =IF(COUNTA(FJ9:FQ9)=0, "", COUNTA(FJ9:FQ9) - SUMPRODUCT(--ISNUMBER(SEARCH("m", FJ9:FQ9)))) | GD9: =IFERROR(ROUND(AVERAGE(FT9,FV9,FX9,FZ9,GB9), 2), "") | GM9: =IF(COUNTA(GE9:GL9)=0, "", SUMPRODUCT(--ISNUMBER(SEARCH("m", GE9:GL9)))) | GN9: =IF(COUNTA(GE9:GL9)=0, "", COUNTA(GE9:GL9) - SUMPRODUCT(--ISNUMBER(SEARCH("m", GE9:GL9)))) | GY9: =IFERROR(ROUND(AVERAGE(GO9,GQ9,GS9,GU9,GW9), 2), "") | HH9: =IF(COUNTA(GZ9:HG9)=0, "", SUMPRODUCT(--ISNUMBER(SEARCH("m", GZ9:HG9)))) | HI9: =IF(COUNTA(GZ9:HG9)=0, "", COUNTA(GZ9:HG9) - SUMPRODUCT(--ISNUMBER(SEARCH("m", GZ9:HG9)))) | HT9: =IFERROR(ROUND(AVERAGE(HJ9,HL9,HN9,HP9,HR9), 2), "") | IC9: =IF(COUNTA(HU9:IB9)=0, "", SUMPRODUCT(--ISNUMBER(SEARCH("m", HU9:IB9)))) | ID9: =IF(COUNTA(HU9:IB9)=0, "", COUNTA(HU9:IB9) - SUMPRODUCT(--ISNUMBER(SEARCH("m", HU9:IB9)))) | IO9: =IFERROR(ROUND(AVERAGE(IE9,IG9,II9,IK9,IM9), 2), "") | IX9: =IF(COUNTA(IP9:IW9)=0, "", SUMPRODUCT(--ISNUMBER(SEARCH("m", IP9:IW9)))) | IY9: =IF(COUNTA(IP9:IW9)=0, "", COUNTA(IP9:IW9) - SUMPRODUCT(--ISNUMBER(SEARCH("m", IP9:IW9)))) | JJ9: =IFERROR(ROUND(AVERAGE(IZ9,JB9,JD9,JF9,JH9), 2), "") | JS9: =IF(COUNTA(JK9:JR9)=0, "", SUMPRODUCT(--ISNUMBER(SEARCH("m", JK9:JR9)))) | JT9: =IF(COUNTA(JK9:JR9)=0, "", COUNTA(JK9:JR9) - SUMPRODUCT(--ISNUMBER(SEARCH("m", JK9:JR9)))) | KE9: =IFERROR(ROUND(AVERAGE(JU9,JW9,JY9,KA9,KC9), 2), "") | KN9: =IF(COUNTA(KF9:KM9)=0, "", SUMPRODUCT(--ISNUMBER(SEARCH("m", KF9:KM9)))) | KO9: =IF(COUNTA(KF9:KM9)=0, "", COUNTA(KF9:KM9) - SUMPRODUCT(--ISNUMBER(SEARCH("m", KF9:KM9))))
A10: 2 | B10: BARA D. ADRIAN DANIEL | C10: 14 | D10: 126/77 | E10: =IFERROR(ROUND(AVERAGE(R10,AM10,BH10,CC10,CX10,DS10,EN10,FI10,GD10,GY10,HT10,IO10,JJ10,KE10), 2), "") | F10: =IF(SUM(AB10,AW10,BR10,CM10,DH10,EC10,EX10,FS10,GN10,HI10,ID10,IY10,JT10,KO10)=0, "", SUM(AB10,AW10,BR10,CM10,DH10,EC10,EX10,FS10,GN10,HI10,ID10,IY10,JT10,KO10)) | G10: =IF(SUM(AA10,AV10,BQ10,CL10,DG10,EB10,EW10,FR10,GM10,HH10,IC10,IX10,JS10,KN10)=0, "", SUM(AA10,AV10,BQ10,CL10,DG10,EB10,EW10,FR10,GM10,HH10,IC10,IX10,JS10,KN10)) | R10: =IFERROR(ROUND(AVERAGE(H10,J10,L10,N10,P10), 2), "") | AA10: =IF(COUNTA(S10:Z10)=0, "", SUMPRODUCT(--ISNUMBER(SEARCH("m", S10:Z10)))) | AB10: =IF(COUNTA(S10:Z10)=0, "", COUNTA(S10:Z10) - SUMPRODUCT(--ISNUMBER(SEARCH("m", S10:Z10)))) | AM10: =IFERROR(ROUND(AVERAGE(AC10,AE10,AG10,AI10,AK10), 2), "") | AV10: =IF(COUNTA(AN10:AU10)=0, "", SUMPRODUCT(--ISNUMBER(SEARCH("m", AN10:AU10)))) | AW10: =IF(COUNTA(AN10:AU10)=0, "", COUNTA(AN10:AU10) - SUMPRODUCT(--ISNUMBER(SEARCH("m", AN10:AU10)))) | BH10: =IFERROR(ROUND(AVERAGE(AX10,AZ10,BB10,BD10,BF10), 2), "") | BQ10: =IF(COUNTA(BI10:BP10)=0, "", SUMPRODUCT(--ISNUMBER(SEARCH("m", BI10:BP10)))) | BR10: =IF(COUNTA(BI10:BP10)=0, "", COUNTA(BI10:BP10) - SUMPRODUCT(--ISNUMBER(SEARCH("m", BI10:BP10)))) | CC10: =IFERROR(ROUND(AVERAGE(BS10,BU10,BW10,BY10,CA10), 2), "") | CL10: =IF(COUNTA(CD10:CK10)=0, "", SUMPRODUCT(--ISNUMBER(SEARCH("m", CD10:CK10)))) | CM10: =IF(COUNTA(CD10:CK10)=0, "", COUNTA(CD10:CK10) - SUMPRODUCT(--ISNUMBER(SEARCH("m", CD10:CK10)))) | CX10: =IFERROR(ROUND(AVERAGE(CN10,CP10,CR10,CT10,CV10), 2), "") | DG10: =IF(COUNTA(CY10:DF10)=0, "", SUMPRODUCT(--ISNUMBER(SEARCH("m", CY10:DF10)))) | DH10: =IF(COUNTA(CY10:DF10)=0, "", COUNTA(CY10:DF10) - SUMPRODUCT(--ISNUMBER(SEARCH("m", CY10:DF10)))) | DS10: =IFERROR(ROUND(AVERAGE(DI10,DK10,DM10,DO10,DQ10), 2), "") | EB10: =IF(COUNTA(DT10:EA10)=0, "", SUMPRODUCT(--ISNUMBER(SEARCH("m", DT10:EA10)))) | EC10: =IF(COUNTA(DT10:EA10)=0, "", COUNTA(DT10:EA10) - SUMPRODUCT(--ISNUMBER(SEARCH("m", DT10:EA10)))) | EN10: =IFERROR(ROUND(AVERAGE(ED10,EF10,EH10,EJ10,EL10), 2), "") | EW10: =IF(COUNTA(EO10:EV10)=0, "", SUMPRODUCT(--ISNUMBER(SEARCH("m", EO10:EV10)))) | EX10: =IF(COUNTA(EO10:EV10)=0, "", COUNTA(EO10:EV10) - SUMPRODUCT(--ISNUMBER(SEARCH("m", EO10:EV10)))) | FI10: =IFERROR(ROUND(AVERAGE(EY10,FA10,FC10,FE10,FG10), 2), "") | FR10: =IF(COUNTA(FJ10:FQ10)=0, "", SUMPRODUCT(--ISNUMBER(SEARCH("m", FJ10:FQ10)))) | FS10: =IF(COUNTA(FJ10:FQ10)=0, "", COUNTA(FJ10:FQ10) - SUMPRODUCT(--ISNUMBER(SEARCH("m", FJ10:FQ10)))) | GD10: =IFERROR(ROUND(AVERAGE(FT10,FV10,FX10,FZ10,GB10), 2), "") | GM10: =IF(COUNTA(GE10:GL10)=0, "", SUMPRODUCT(--ISNUMBER(SEARCH("m", GE10:GL10)))) | GN10: =IF(COUNTA(GE10:GL10)=0, "", COUNTA(GE10:GL10) - SUMPRODUCT(--ISNUMBER(SEARCH("m", GE10:GL10)))) | GY10: =IFERROR(ROUND(AVERAGE(GO10,GQ10,GS10,GU10,GW10), 2), "") | HH10: =IF(COUNTA(GZ10:HG10)=0, "", SUMPRODUCT(--ISNUMBER(SEARCH("m", GZ10:HG10)))) | HI10: =IF(COUNTA(GZ10:HG10)=0, "", COUNTA(GZ10:HG10) - SUMPRODUCT(--ISNUMBER(SEARCH("m", GZ10:HG10)))) | HT10: =IFERROR(ROUND(AVERAGE(HJ10,HL10,HN10,HP10,HR10), 2), "") | IC10: =IF(COUNTA(HU10:IB10)=0, "", SUMPRODUCT(--ISNUMBER(SEARCH("m", HU10:IB10)))) | ID10: =IF(COUNTA(HU10:IB10)=0, "", COUNTA(HU10:IB10) - SUMPRODUCT(--ISNUMBER(SEARCH("m", HU10:IB10)))) | IO10: =IFERROR(ROUND(AVERAGE(IE10,IG10,II10,IK10,IM10), 2), "") | IX10: =IF(COUNTA(IP10:IW10)=0, "", SUMPRODUCT(--ISNUMBER(SEARCH("m", IP10:IW10)))) | IY10: =IF(COUNTA(IP10:IW10)=0, "", COUNTA(IP10:IW10) - SUMPRODUCT(--ISNUMBER(SEARCH("m", IP10:IW10)))) | JJ10: =IFERROR(ROUND(AVERAGE(IZ10,JB10,JD10,JF10,JH10), 2), "") | JS10: =IF(COUNTA(JK10:JR10)=0, "", SUMPRODUCT(--ISNUMBER(SEARCH("m", JK10:JR10)))) | JT10: =IF(COUNTA(JK10:JR10)=0, "", COUNTA(JK10:JR10) - SUMPRODUCT(--ISNUMBER(SEARCH("m", JK10:JR10)))) | KE10: =IFERROR(ROUND(AVERAGE(JU10,JW10,JY10,KA10,KC10), 2), "") | KN10: =IF(COUNTA(KF10:KM10)=0, "", SUMPRODUCT(--ISNUMBER(SEARCH("m", KF10:KM10)))) | KO10: =IF(COUNTA(KF10:KM10)=0, "", COUNTA(KF10:KM10) - SUMPRODUCT(--ISNUMBER(SEARCH("m", KF10:KM10))))
A11: 3 | B11: BUDACĂ I. MARIA MADALINA | C11: 15 | D11: 126/78 | E11: =IFERROR(ROUND(AVERAGE(R11,AM11,BH11,CC11,CX11,DS11,EN11,FI11,GD11,GY11,HT11,IO11,JJ11,KE11), 2), "") | F11: =IF(SUM(AB11,AW11,BR11,CM11,DH11,EC11,EX11,FS11,GN11,HI11,ID11,IY11,JT11,KO11)=0, "", SUM(AB11,AW11,BR11,CM11,DH11,EC11,EX11,FS11,GN11,HI11,ID11,IY11,JT11,KO11)) | G11: =IF(SUM(AA11,AV11,BQ11,CL11,DG11,EB11,EW11,FR11,GM11,HH11,IC11,IX11,JS11,KN11)=0, "", SUM(AA11,AV11,BQ11,CL11,DG11,EB11,EW11,FR11,GM11,HH11,IC11,IX11,JS11,KN11)) | R11: =IFERROR(ROUND(AVERAGE(H11,J11,L11,N11,P11), 2), "") | AA11: =IF(COUNTA(S11:Z11)=0, "", SUMPRODUCT(--ISNUMBER(SEARCH("m", S11:Z11)))) | AB11: =IF(COUNTA(S11:Z11)=0, "", COUNTA(S11:Z11) - SUMPRODUCT(--ISNUMBER(SEARCH("m", S11:Z11)))) | AM11: =IFERROR(ROUND(AVERAGE(AC11,AE11,AG11,AI11,AK11), 2), "") | AV11: =IF(COUNTA(AN11:AU11)=0, "", SUMPRODUCT(--ISNUMBER(SEARCH("m", AN11:AU11)))) | AW11: =IF(COUNTA(AN11:AU11)=0, "", COUNTA(AN11:AU11) - SUMPRODUCT(--ISNUMBER(SEARCH("m", AN11:AU11)))) | BH11: =IFERROR(ROUND(AVERAGE(AX11,AZ11,BB11,BD11,BF11), 2), "") | BQ11: =IF(COUNTA(BI11:BP11)=0, "", SUMPRODUCT(--ISNUMBER(SEARCH("m", BI11:BP11)))) | BR11: =IF(COUNTA(BI11:BP11)=0, "", COUNTA(BI11:BP11) - SUMPRODUCT(--ISNUMBER(SEARCH("m", BI11:BP11)))) | CC11: =IFERROR(ROUND(AVERAGE(BS11,BU11,BW11,BY11,CA11), 2), "") | CL11: =IF(COUNTA(CD11:CK11)=0, "", SUMPRODUCT(--ISNUMBER(SEARCH("m", CD11:CK11)))) | CM11: =IF(COUNTA(CD11:CK11)=0, "", COUNTA(CD11:CK11) - SUMPRODUCT(--ISNUMBER(SEARCH("m", CD11:CK11)))) | CX11: =IFERROR(ROUND(AVERAGE(CN11,CP11,CR11,CT11,CV11), 2), "") | DG11: =IF(COUNTA(CY11:DF11)=0, "", SUMPRODUCT(--ISNUMBER(SEARCH("m", CY11:DF11)))) | DH11: =IF(COUNTA(CY11:DF11)=0, "", COUNTA(CY11:DF11) - SUMPRODUCT(--ISNUMBER(SEARCH("m", CY11:DF11)))) | DS11: =IFERROR(ROUND(AVERAGE(DI11,DK11,DM11,DO11,DQ11), 2), "") | EB11: =IF(COUNTA(DT11:EA11)=0, "", SUMPRODUCT(--ISNUMBER(SEARCH("m", DT11:EA11)))) | EC11: =IF(COUNTA(DT11:EA11)=0, "", COUNTA(DT11:EA11) - SUMPRODUCT(--ISNUMBER(SEARCH("m", DT11:EA11)))) | EN11: =IFERROR(ROUND(AVERAGE(ED11,EF11,EH11,EJ11,EL11), 2), "") | EW11: =IF(COUNTA(EO11:EV11)=0, "", SUMPRODUCT(--ISNUMBER(SEARCH("m", EO11:EV11)))) | EX11: =IF(COUNTA(EO11:EV11)=0, "", COUNTA(EO11:EV11) - SUMPRODUCT(--ISNUMBER(SEARCH("m", EO11:EV11)))) | FI11: =IFERROR(ROUND(AVERAGE(EY11,FA11,FC11,FE11,FG11), 2), "") | FR11: =IF(COUNTA(FJ11:FQ11)=0, "", SUMPRODUCT(--ISNUMBER(SEARCH("m", FJ11:FQ11)))) | FS11: =IF(COUNTA(FJ11:FQ11)=0, "", COUNTA(FJ11:FQ11) - SUMPRODUCT(--ISNUMBER(SEARCH("m", FJ11:FQ11)))) | GD11: =IFERROR(ROUND(AVERAGE(FT11,FV11,FX11,FZ11,GB11), 2), "") | GM11: =IF(COUNTA(GE11:GL11)=0, "", SUMPRODUCT(--ISNUMBER(SEARCH("m", GE11:GL11)))) | GN11: =IF(COUNTA(GE11:GL11)=0, "", COUNTA(GE11:GL11) - SUMPRODUCT(--ISNUMBER(SEARCH("m", GE11:GL11)))) | GY11: =IFERROR(ROUND(AVERAGE(GO11,GQ11,GS11,GU11,GW11), 2), "") | HH11: =IF(COUNTA(GZ11:HG11)=0, "", SUMPRODUCT(--ISNUMBER(SEARCH("m", GZ11:HG11)))) | HI11: =IF(COUNTA(GZ11:HG11)=0, "", COUNTA(GZ11:HG11) - SUMPRODUCT(--ISNUMBER(SEARCH("m", GZ11:HG11)))) | HT11: =IFERROR(ROUND(AVERAGE(HJ11,HL11,HN11,HP11,HR11), 2), "") | IC11: =IF(COUNTA(HU11:IB11)=0, "", SUMPRODUCT(--ISNUMBER(SEARCH("m", HU11:IB11)))) | ID11: =IF(COUNTA(HU11:IB11)=0, "", COUNTA(HU11:IB11) - SUMPRODUCT(--ISNUMBER(SEARCH("m", HU11:IB11)))) | IO11: =IFERROR(ROUND(AVERAGE(IE11,IG11,II11,IK11,IM11), 2), "") | IX11: =IF(COUNTA(IP11:IW11)=0, "", SUMPRODUCT(--ISNUMBER(SEARCH("m", IP11:IW11)))) | IY11: =IF(COUNTA(IP11:IW11)=0, "", COUNTA(IP11:IW11) - SUMPRODUCT(--ISNUMBER(SEARCH("m", IP11:IW11)))) | JJ11: =IFERROR(ROUND(AVERAGE(IZ11,JB11,JD11,JF11,JH11), 2), "") | JS11: =IF(COUNTA(JK11:JR11)=0, "", SUMPRODUCT(--ISNUMBER(SEARCH("m", JK11:JR11)))) | JT11: =IF(COUNTA(JK11:JR11)=0, "", COUNTA(JK11:JR11) - SUMPRODUCT(--ISNUMBER(SEARCH("m", JK11:JR11)))) | KE11: =IFERROR(ROUND(AVERAGE(JU11,JW11,JY11,KA11,KC11), 2), "") | KN11: =IF(COUNTA(KF11:KM11)=0, "", SUMPRODUCT(--ISNUMBER(SEARCH("m", KF11:KM11)))) | KO11: =IF(COUNTA(KF11:KM11)=0, "", COUNTA(KF11:KM11) - SUMPRODUCT(--ISNUMBER(SEARCH("m", KF11:KM11))))
A12: 4 | B12: BUDULĂU I.M. VLAD IOAN | C12: 16 | D12: 126/79 | E12: =IFERROR(ROUND(AVERAGE(R12,AM12,BH12,CC12,CX12,DS12,EN12,FI12,GD12,GY12,HT12,IO12,JJ12,KE12), 2), "") | F12: =IF(SUM(AB12,AW12,BR12,CM12,DH12,EC12,EX12,FS12,GN12,HI12,ID12,IY12,JT12,KO12)=0, "", SUM(AB12,AW12,BR12,CM12,DH12,EC12,EX12,FS12,GN12,HI12,ID12,IY12,JT12,KO12)) | G12: =IF(SUM(AA12,AV12,BQ12,CL12,DG12,EB12,EW12,FR12,GM12,HH12,IC12,IX12,JS12,KN12)=0, "", SUM(AA12,AV12,BQ12,CL12,DG12,EB12,EW12,FR12,GM12,HH12,IC12,IX12,JS12,KN12)) | R12: =IFERROR(ROUND(AVERAGE(H12,J12,L12,N12,P12), 2), "") | AA12: =IF(COUNTA(S12:Z12)=0, "", SUMPRODUCT(--ISNUMBER(SEARCH("m", S12:Z12)))) | AB12: =IF(COUNTA(S12:Z12)=0, "", COUNTA(S12:Z12) - SUMPRODUCT(--ISNUMBER(SEARCH("m", S12:Z12)))) | AM12: =IFERROR(ROUND(AVERAGE(AC12,AE12,AG12,AI12,AK12), 2), "") | AV12: =IF(COUNTA(AN12:AU12)=0, "", SUMPRODUCT(--ISNUMBER(SEARCH("m", AN12:AU12)))) | AW12: =IF(COUNTA(AN12:AU12)=0, "", COUNTA(AN12:AU12) - SUMPRODUCT(--ISNUMBER(SEARCH("m", AN12:AU12)))) | BH12: =IFERROR(ROUND(AVERAGE(AX12,AZ12,BB12,BD12,BF12), 2), "") | BQ12: =IF(COUNTA(BI12:BP12)=0, "", SUMPRODUCT(--ISNUMBER(SEARCH("m", BI12:BP12)))) | BR12: =IF(COUNTA(BI12:BP12)=0, "", COUNTA(BI12:BP12) - SUMPRODUCT(--ISNUMBER(SEARCH("m", BI12:BP12)))) | CC12: =IFERROR(ROUND(AVERAGE(BS12,BU12,BW12,BY12,CA12), 2), "") | CL12: =IF(COUNTA(CD12:CK12)=0, "", SUMPRODUCT(--ISNUMBER(SEARCH("m", CD12:CK12)))) | CM12: =IF(COUNTA(CD12:CK12)=0, "", COUNTA(CD12:CK12) - SUMPRODUCT(--ISNUMBER(SEARCH("m", CD12:CK12)))) | CX12: =IFERROR(ROUND(AVERAGE(CN12,CP12,CR12,CT12,CV12), 2), "") | DG12: =IF(COUNTA(CY12:DF12)=0, "", SUMPRODUCT(--ISNUMBER(SEARCH("m", CY12:DF12)))) | DH12: =IF(COUNTA(CY12:DF12)=0, "", COUNTA(CY12:DF12) - SUMPRODUCT(--ISNUMBER(SEARCH("m", CY12:DF12)))) | DS12: =IFERROR(ROUND(AVERAGE(DI12,DK12,DM12,DO12,DQ12), 2), "") | EB12: =IF(COUNTA(DT12:EA12)=0, "", SUMPRODUCT(--ISNUMBER(SEARCH("m", DT12:EA12)))) | EC12: =IF(COUNTA(DT12:EA12)=0, "", COUNTA(DT12:EA12) - SUMPRODUCT(--ISNUMBER(SEARCH("m", DT12:EA12)))) | EN12: =IFERROR(ROUND(AVERAGE(ED12,EF12,EH12,EJ12,EL12), 2), "") | EW12: =IF(COUNTA(EO12:EV12)=0, "", SUMPRODUCT(--ISNUMBER(SEARCH("m", EO12:EV12)))) | EX12: =IF(COUNTA(EO12:EV12)=0, "", COUNTA(EO12:EV12) - SUMPRODUCT(--ISNUMBER(SEARCH("m", EO12:EV12)))) | FI12: =IFERROR(ROUND(AVERAGE(EY12,FA12,FC12,FE12,FG12), 2), "") | FR12: =IF(COUNTA(FJ12:FQ12)=0, "", SUMPRODUCT(--ISNUMBER(SEARCH("m", FJ12:FQ12)))) | FS12: =IF(COUNTA(FJ12:FQ12)=0, "", COUNTA(FJ12:FQ12) - SUMPRODUCT(--ISNUMBER(SEARCH("m", FJ12:FQ12)))) | GD12: =IFERROR(ROUND(AVERAGE(FT12,FV12,FX12,FZ12,GB12), 2), "") | GM12: =IF(COUNTA(GE12:GL12)=0, "", SUMPRODUCT(--ISNUMBER(SEARCH("m", GE12:GL12)))) | GN12: =IF(COUNTA(GE12:GL12)=0, "", COUNTA(GE12:GL12) - SUMPRODUCT(--ISNUMBER(SEARCH("m", GE12:GL12)))) | GY12: =IFERROR(ROUND(AVERAGE(GO12,GQ12,GS12,GU12,GW12), 2), "") | HH12: =IF(COUNTA(GZ12:HG12)=0, "", SUMPRODUCT(--ISNUMBER(SEARCH("m", GZ12:HG12)))) | HI12: =IF(COUNTA(GZ12:HG12)=0, "", COUNTA(GZ12:HG12) - SUMPRODUCT(--ISNUMBER(SEARCH("m", GZ12:HG12)))) | HT12: =IFERROR(ROUND(AVERAGE(HJ12,HL12,HN12,HP12,HR12), 2), "") | IC12: =IF(COUNTA(HU12:IB12)=0, "", SUMPRODUCT(--ISNUMBER(SEARCH("m", HU12:IB12)))) | ID12: =IF(COUNTA(HU12:IB12)=0, "", COUNTA(HU12:IB12) - SUMPRODUCT(--ISNUMBER(SEARCH("m", HU12:IB12)))) | IO12: =IFERROR(ROUND(AVERAGE(IE12,IG12,II12,IK12,IM12), 2), "") | IX12: =IF(COUNTA(IP12:IW12)=0, "", SUMPRODUCT(--ISNUMBER(SEARCH("m", IP12:IW12)))) | IY12: =IF(COUNTA(IP12:IW12)=0, "", COUNTA(IP12:IW12) - SUMPRODUCT(--ISNUMBER(SEARCH("m", IP12:IW12)))) | JJ12: =IFERROR(ROUND(AVERAGE(IZ12,JB12,JD12,JF12,JH12), 2), "") | JS12: =IF(COUNTA(JK12:JR12)=0, "", SUMPRODUCT(--ISNUMBER(SEARCH("m", JK12:JR12)))) | JT12: =IF(COUNTA(JK12:JR12)=0, "", COUNTA(JK12:JR12) - SUMPRODUCT(--ISNUMBER(SEARCH("m", JK12:JR12)))) | KE12: =IFERROR(ROUND(AVERAGE(JU12,JW12,JY12,KA12,KC12), 2), "") | KN12: =IF(COUNTA(KF12:KM12)=0, "", SUMPRODUCT(--ISNUMBER(SEARCH("m", KF12:KM12)))) | KO12: =IF(COUNTA(KF12:KM12)=0, "", COUNTA(KF12:KM12) - SUMPRODUCT(--ISNUMBER(SEARCH("m", KF12:KM12))))
A13: 5 | B13: CHESZOVAN D.E. IRINA JULIETA | C13: 17 | D13: 126/80 | E13: =IFERROR(ROUND(AVERAGE(R13,AM13,BH13,CC13,CX13,DS13,EN13,FI13,GD13,GY13,HT13,IO13,JJ13,KE13), 2), "") | F13: =IF(SUM(AB13,AW13,BR13,CM13,DH13,EC13,EX13,FS13,GN13,HI13,ID13,IY13,JT13,KO13)=0, "", SUM(AB13,AW13,BR13,CM13,DH13,EC13,EX13,FS13,GN13,HI13,ID13,IY13,JT13,KO13)) | G13: =IF(SUM(AA13,AV13,BQ13,CL13,DG13,EB13,EW13,FR13,GM13,HH13,IC13,IX13,JS13,KN13)=0, "", SUM(AA13,AV13,BQ13,CL13,DG13,EB13,EW13,FR13,GM13,HH13,IC13,IX13,JS13,KN13)) | R13: =IFERROR(ROUND(AVERAGE(H13,J13,L13,N13,P13), 2), "") | AA13: =IF(COUNTA(S13:Z13)=0, "", SUMPRODUCT(--ISNUMBER(SEARCH("m", S13:Z13)))) | AB13: =IF(COUNTA(S13:Z13)=0, "", COUNTA(S13:Z13) - SUMPRODUCT(--ISNUMBER(SEARCH("m", S13:Z13)))) | AM13: =IFERROR(ROUND(AVERAGE(AC13,AE13,AG13,AI13,AK13), 2), "") | AV13: =IF(COUNTA(AN13:AU13)=0, "", SUMPRODUCT(--ISNUMBER(SEARCH("m", AN13:AU13)))) | AW13: =IF(COUNTA(AN13:AU13)=0, "", COUNTA(AN13:AU13) - SUMPRODUCT(--ISNUMBER(SEARCH("m", AN13:AU13)))) | BH13: =IFERROR(ROUND(AVERAGE(AX13,AZ13,BB13,BD13,BF13), 2), "") | BQ13: =IF(COUNTA(BI13:BP13)=0, "", SUMPRODUCT(--ISNUMBER(SEARCH("m", BI13:BP13)))) | BR13: =IF(COUNTA(BI13:BP13)=0, "", COUNTA(BI13:BP13) - SUMPRODUCT(--ISNUMBER(SEARCH("m", BI13:BP13)))) | CC13: =IFERROR(ROUND(AVERAGE(BS13,BU13,BW13,BY13,CA13), 2), "") | CL13: =IF(COUNTA(CD13:CK13)=0, "", SUMPRODUCT(--ISNUMBER(SEARCH("m", CD13:CK13)))) | CM13: =IF(COUNTA(CD13:CK13)=0, "", COUNTA(CD13:CK13) - SUMPRODUCT(--ISNUMBER(SEARCH("m", CD13:CK13)))) | CX13: =IFERROR(ROUND(AVERAGE(CN13,CP13,CR13,CT13,CV13), 2), "") | DG13: =IF(COUNTA(CY13:DF13)=0, "", SUMPRODUCT(--ISNUMBER(SEARCH("m", CY13:DF13)))) | DH13: =IF(COUNTA(CY13:DF13)=0, "", COUNTA(CY13:DF13) - SUMPRODUCT(--ISNUMBER(SEARCH("m", CY13:DF13)))) | DS13: =IFERROR(ROUND(AVERAGE(DI13,DK13,DM13,DO13,DQ13), 2), "") | EB13: =IF(COUNTA(DT13:EA13)=0, "", SUMPRODUCT(--ISNUMBER(SEARCH("m", DT13:EA13)))) | EC13: =IF(COUNTA(DT13:EA13)=0, "", COUNTA(DT13:EA13) - SUMPRODUCT(--ISNUMBER(SEARCH("m", DT13:EA13)))) | EN13: =IFERROR(ROUND(AVERAGE(ED13,EF13,EH13,EJ13,EL13), 2), "") | EW13: =IF(COUNTA(EO13:EV13)=0, "", SUMPRODUCT(--ISNUMBER(SEARCH("m", EO13:EV13)))) | EX13: =IF(COUNTA(EO13:EV13)=0, "", COUNTA(EO13:EV13) - SUMPRODUCT(--ISNUMBER(SEARCH("m", EO13:EV13)))) | FI13: =IFERROR(ROUND(AVERAGE(EY13,FA13,FC13,FE13,FG13), 2), "") | FR13: =IF(COUNTA(FJ13:FQ13)=0, "", SUMPRODUCT(--ISNUMBER(SEARCH("m", FJ13:FQ13)))) | FS13: =IF(COUNTA(FJ13:FQ13)=0, "", COUNTA(FJ13:FQ13) - SUMPRODUCT(--ISNUMBER(SEARCH("m", FJ13:FQ13)))) | GD13: =IFERROR(ROUND(AVERAGE(FT13,FV13,FX13,FZ13,GB13), 2), "") | GM13: =IF(COUNTA(GE13:GL13)=0, "", SUMPRODUCT(--ISNUMBER(SEARCH("m", GE13:GL13)))) | GN13: =IF(COUNTA(GE13:GL13)=0, "", COUNTA(GE13:GL13) - SUMPRODUCT(--ISNUMBER(SEARCH("m", GE13:GL13)))) | GY13: =IFERROR(ROUND(AVERAGE(GO13,GQ13,GS13,GU13,GW13), 2), "") | HH13: =IF(COUNTA(GZ13:HG13)=0, "", SUMPRODUCT(--ISNUMBER(SEARCH("m", GZ13:HG13)))) | HI13: =IF(COUNTA(GZ13:HG13)=0, "", COUNTA(GZ13:HG13) - SUMPRODUCT(--ISNUMBER(SEARCH("m", GZ13:HG13)))) | HT13: =IFERROR(ROUND(AVERAGE(HJ13,HL13,HN13,HP13,HR13), 2), "") | IC13: =IF(COUNTA(HU13:IB13)=0, "", SUMPRODUCT(--ISNUMBER(SEARCH("m", HU13:IB13)))) | ID13: =IF(COUNTA(HU13:IB13)=0, "", COUNTA(HU13:IB13) - SUMPRODUCT(--ISNUMBER(SEARCH("m", HU13:IB13)))) | IO13: =IFERROR(ROUND(AVERAGE(IE13,IG13,II13,IK13,IM13), 2), "") | IX13: =IF(COUNTA(IP13:IW13)=0, "", SUMPRODUCT(--ISNUMBER(SEARCH("m", IP13:IW13)))) | IY13: =IF(COUNTA(IP13:IW13)=0, "", COUNTA(IP13:IW13) - SUMPRODUCT(--ISNUMBER(SEARCH("m", IP13:IW13)))) | JJ13: =IFERROR(ROUND(AVERAGE(IZ13,JB13,JD13,JF13,JH13), 2), "") | JS13: =IF(COUNTA(JK13:JR13)=0, "", SUMPRODUCT(--ISNUMBER(SEARCH("m", JK13:JR13)))) | JT13: =IF(COUNTA(JK13:JR13)=0, "", COUNTA(JK13:JR13) - SUMPRODUCT(--ISNUMBER(SEARCH("m", JK13:JR13)))) | KE13: =IFERROR(ROUND(AVERAGE(JU13,JW13,JY13,KA13,KC13), 2), "") | KN13: =IF(COUNTA(KF13:KM13)=0, "", SUMPRODUCT(--ISNUMBER(SEARCH("m", KF13:KM13)))) | KO13: =IF(COUNTA(KF13:KM13)=0, "", COUNTA(KF13:KM13) - SUMPRODUCT(--ISNUMBER(SEARCH("m", KF13:KM13))))
A14: 6 | B14: CIURCUI V. DIANA | C14: 18 | D14: 126/81 | E14: =IFERROR(ROUND(AVERAGE(R14,AM14,BH14,CC14,CX14,DS14,EN14,FI14,GD14,GY14,HT14,IO14,JJ14,KE14), 2), "") | F14: =IF(SUM(AB14,AW14,BR14,CM14,DH14,EC14,EX14,FS14,GN14,HI14,ID14,IY14,JT14,KO14)=0, "", SUM(AB14,AW14,BR14,CM14,DH14,EC14,EX14,FS14,GN14,HI14,ID14,IY14,JT14,KO14)) | G14: =IF(SUM(AA14,AV14,BQ14,CL14,DG14,EB14,EW14,FR14,GM14,HH14,IC14,IX14,JS14,KN14)=0, "", SUM(AA14,AV14,BQ14,CL14,DG14,EB14,EW14,FR14,GM14,HH14,IC14,IX14,JS14,KN14)) | R14: =IFERROR(ROUND(AVERAGE(H14,J14,L14,N14,P14), 2), "") | AA14: =IF(COUNTA(S14:Z14)=0, "", SUMPRODUCT(--ISNUMBER(SEARCH("m", S14:Z14)))) | AB14: =IF(COUNTA(S14:Z14)=0, "", COUNTA(S14:Z14) - SUMPRODUCT(--ISNUMBER(SEARCH("m", S14:Z14)))) | AM14: =IFERROR(ROUND(AVERAGE(AC14,AE14,AG14,AI14,AK14), 2), "") | AV14: =IF(COUNTA(AN14:AU14)=0, "", SUMPRODUCT(--ISNUMBER(SEARCH("m", AN14:AU14)))) | AW14: =IF(COUNTA(AN14:AU14)=0, "", COUNTA(AN14:AU14) - SUMPRODUCT(--ISNUMBER(SEARCH("m", AN14:AU14)))) | BH14: =IFERROR(ROUND(AVERAGE(AX14,AZ14,BB14,BD14,BF14), 2), "") | BQ14: =IF(COUNTA(BI14:BP14)=0, "", SUMPRODUCT(--ISNUMBER(SEARCH("m", BI14:BP14)))) | BR14: =IF(COUNTA(BI14:BP14)=0, "", COUNTA(BI14:BP14) - SUMPRODUCT(--ISNUMBER(SEARCH("m", BI14:BP14)))) | CC14: =IFERROR(ROUND(AVERAGE(BS14,BU14,BW14,BY14,CA14), 2), "") | CL14: =IF(COUNTA(CD14:CK14)=0, "", SUMPRODUCT(--ISNUMBER(SEARCH("m", CD14:CK14)))) | CM14: =IF(COUNTA(CD14:CK14)=0, "", COUNTA(CD14:CK14) - SUMPRODUCT(--ISNUMBER(SEARCH("m", CD14:CK14)))) | CX14: =IFERROR(ROUND(AVERAGE(CN14,CP14,CR14,CT14,CV14), 2), "") | DG14: =IF(COUNTA(CY14:DF14)=0, "", SUMPRODUCT(--ISNUMBER(SEARCH("m", CY14:DF14)))) | DH14: =IF(COUNTA(CY14:DF14)=0, "", COUNTA(CY14:DF14) - SUMPRODUCT(--ISNUMBER(SEARCH("m", CY14:DF14)))) | DS14: =IFERROR(ROUND(AVERAGE(DI14,DK14,DM14,DO14,DQ14), 2), "") | EB14: =IF(COUNTA(DT14:EA14)=0, "", SUMPRODUCT(--ISNUMBER(SEARCH("m", DT14:EA14)))) | EC14: =IF(COUNTA(DT14:EA14)=0, "", COUNTA(DT14:EA14) - SUMPRODUCT(--ISNUMBER(SEARCH("m", DT14:EA14)))) | EN14: =IFERROR(ROUND(AVERAGE(ED14,EF14,EH14,EJ14,EL14), 2), "") | EW14: =IF(COUNTA(EO14:EV14)=0, "", SUMPRODUCT(--ISNUMBER(SEARCH("m", EO14:EV14)))) | EX14: =IF(COUNTA(EO14:EV14)=0, "", COUNTA(EO14:EV14) - SUMPRODUCT(--ISNUMBER(SEARCH("m", EO14:EV14)))) | FI14: =IFERROR(ROUND(AVERAGE(EY14,FA14,FC14,FE14,FG14), 2), "") | FR14: =IF(COUNTA(FJ14:FQ14)=0, "", SUMPRODUCT(--ISNUMBER(SEARCH("m", FJ14:FQ14)))) | FS14: =IF(COUNTA(FJ14:FQ14)=0, "", COUNTA(FJ14:FQ14) - SUMPRODUCT(--ISNUMBER(SEARCH("m", FJ14:FQ14)))) | GD14: =IFERROR(ROUND(AVERAGE(FT14,FV14,FX14,FZ14,GB14), 2), "") | GM14: =IF(COUNTA(GE14:GL14)=0, "", SUMPRODUCT(--ISNUMBER(SEARCH("m", GE14:GL14)))) | GN14: =IF(COUNTA(GE14:GL14)=0, "", COUNTA(GE14:GL14) - SUMPRODUCT(--ISNUMBER(SEARCH("m", GE14:GL14)))) | GY14: =IFERROR(ROUND(AVERAGE(GO14,GQ14,GS14,GU14,GW14), 2), "") | HH14: =IF(COUNTA(GZ14:HG14)=0, "", SUMPRODUCT(--ISNUMBER(SEARCH("m", GZ14:HG14)))) | HI14: =IF(COUNTA(GZ14:HG14)=0, "", COUNTA(GZ14:HG14) - SUMPRODUCT(--ISNUMBER(SEARCH("m", GZ14:HG14)))) | HT14: =IFERROR(ROUND(AVERAGE(HJ14,HL14,HN14,HP14,HR14), 2), "") | IC14: =IF(COUNTA(HU14:IB14)=0, "", SUMPRODUCT(--ISNUMBER(SEARCH("m", HU14:IB14)))) | ID14: =IF(COUNTA(HU14:IB14)=0, "", COUNTA(HU14:IB14) - SUMPRODUCT(--ISNUMBER(SEARCH("m", HU14:IB14)))) | IO14: =IFERROR(ROUND(AVERAGE(IE14,IG14,II14,IK14,IM14), 2), "") | IX14: =IF(COUNTA(IP14:IW14)=0, "", SUMPRODUCT(--ISNUMBER(SEARCH("m", IP14:IW14)))) | IY14: =IF(COUNTA(IP14:IW14)=0, "", COUNTA(IP14:IW14) - SUMPRODUCT(--ISNUMBER(SEARCH("m", IP14:IW14)))) | JJ14: =IFERROR(ROUND(AVERAGE(IZ14,JB14,JD14,JF14,JH14), 2), "") | JS14: =IF(COUNTA(JK14:JR14)=0, "", SUMPRODUCT(--ISNUMBER(SEARCH("m", JK14:JR14)))) | JT14: =IF(COUNTA(JK14:JR14)=0, "", COUNTA(JK14:JR14) - SUMPRODUCT(--ISNUMBER(SEARCH("m", JK14:JR14)))) | KE14: =IFERROR(ROUND(AVERAGE(JU14,JW14,JY14,KA14,KC14), 2), "") | KN14: =IF(COUNTA(KF14:KM14)=0, "", SUMPRODUCT(--ISNUMBER(SEARCH("m", KF14:KM14)))) | KO14: =IF(COUNTA(KF14:KM14)=0, "", COUNTA(KF14:KM14) - SUMPRODUCT(--ISNUMBER(SEARCH("m", KF14:KM14))))
A15: 7 | B15: CORDIȘ M.C. EDUARD IONUȚ | C15: 19 | D15: 126/82 | E15: =IFERROR(ROUND(AVERAGE(R15,AM15,BH15,CC15,CX15,DS15,EN15,FI15,GD15,GY15,HT15,IO15,JJ15,KE15), 2), "") | F15: =IF(SUM(AB15,AW15,BR15,CM15,DH15,EC15,EX15,FS15,GN15,HI15,ID15,IY15,JT15,KO15)=0, "", SUM(AB15,AW15,BR15,CM15,DH15,EC15,EX15,FS15,GN15,HI15,ID15,IY15,JT15,KO15)) | G15: =IF(SUM(AA15,AV15,BQ15,CL15,DG15,EB15,EW15,FR15,GM15,HH15,IC15,IX15,JS15,KN15)=0, "", SUM(AA15,AV15,BQ15,CL15,DG15,EB15,EW15,FR15,GM15,HH15,IC15,IX15,JS15,KN15)) | R15: =IFERROR(ROUND(AVERAGE(H15,J15,L15,N15,P15), 2), "") | AA15: =IF(COUNTA(S15:Z15)=0, "", SUMPRODUCT(--ISNUMBER(SEARCH("m", S15:Z15)))) | AB15: =IF(COUNTA(S15:Z15)=0, "", COUNTA(S15:Z15) - SUMPRODUCT(--ISNUMBER(SEARCH("m", S15:Z15)))) | AM15: =IFERROR(ROUND(AVERAGE(AC15,AE15,AG15,AI15,AK15), 2), "") | AV15: =IF(COUNTA(AN15:AU15)=0, "", SUMPRODUCT(--ISNUMBER(SEARCH("m", AN15:AU15)))) | AW15: =IF(COUNTA(AN15:AU15)=0, "", COUNTA(AN15:AU15) - SUMPRODUCT(--ISNUMBER(SEARCH("m", AN15:AU15)))) | BH15: =IFERROR(ROUND(AVERAGE(AX15,AZ15,BB15,BD15,BF15), 2), "") | BQ15: =IF(COUNTA(BI15:BP15)=0, "", SUMPRODUCT(--ISNUMBER(SEARCH("m", BI15:BP15)))) | BR15: =IF(COUNTA(BI15:BP15)=0, "", COUNTA(BI15:BP15) - SUMPRODUCT(--ISNUMBER(SEARCH("m", BI15:BP15)))) | CC15: =IFERROR(ROUND(AVERAGE(BS15,BU15,BW15,BY15,CA15), 2), "") | CL15: =IF(COUNTA(CD15:CK15)=0, "", SUMPRODUCT(--ISNUMBER(SEARCH("m", CD15:CK15)))) | CM15: =IF(COUNTA(CD15:CK15)=0, "", COUNTA(CD15:CK15) - SUMPRODUCT(--ISNUMBER(SEARCH("m", CD15:CK15)))) | CX15: =IFERROR(ROUND(AVERAGE(CN15,CP15,CR15,CT15,CV15), 2), "") | DG15: =IF(COUNTA(CY15:DF15)=0, "", SUMPRODUCT(--ISNUMBER(SEARCH("m", CY15:DF15)))) | DH15: =IF(COUNTA(CY15:DF15)=0, "", COUNTA(CY15:DF15) - SUMPRODUCT(--ISNUMBER(SEARCH("m", CY15:DF15)))) | DS15: =IFERROR(ROUND(AVERAGE(DI15,DK15,DM15,DO15,DQ15), 2), "") | EB15: =IF(COUNTA(DT15:EA15)=0, "", SUMPRODUCT(--ISNUMBER(SEARCH("m", DT15:EA15)))) | EC15: =IF(COUNTA(DT15:EA15)=0, "", COUNTA(DT15:EA15) - SUMPRODUCT(--ISNUMBER(SEARCH("m", DT15:EA15)))) | EN15: =IFERROR(ROUND(AVERAGE(ED15,EF15,EH15,EJ15,EL15), 2), "") | EW15: =IF(COUNTA(EO15:EV15)=0, "", SUMPRODUCT(--ISNUMBER(SEARCH("m", EO15:EV15)))) | EX15: =IF(COUNTA(EO15:EV15)=0, "", COUNTA(EO15:EV15) - SUMPRODUCT(--ISNUMBER(SEARCH("m", EO15:EV15)))) | FI15: =IFERROR(ROUND(AVERAGE(EY15,FA15,FC15,FE15,FG15), 2), "") | FR15: =IF(COUNTA(FJ15:FQ15)=0, "", SUMPRODUCT(--ISNUMBER(SEARCH("m", FJ15:FQ15)))) | FS15: =IF(COUNTA(FJ15:FQ15)=0, "", COUNTA(FJ15:FQ15) - SUMPRODUCT(--ISNUMBER(SEARCH("m", FJ15:FQ15)))) | GD15: =IFERROR(ROUND(AVERAGE(FT15,FV15,FX15,FZ15,GB15), 2), "") | GM15: =IF(COUNTA(GE15:GL15)=0, "", SUMPRODUCT(--ISNUMBER(SEARCH("m", GE15:GL15)))) | GN15: =IF(COUNTA(GE15:GL15)=0, "", COUNTA(GE15:GL15) - SUMPRODUCT(--ISNUMBER(SEARCH("m", GE15:GL15)))) | GY15: =IFERROR(ROUND(AVERAGE(GO15,GQ15,GS15,GU15,GW15), 2), "") | HH15: =IF(COUNTA(GZ15:HG15)=0, "", SUMPRODUCT(--ISNUMBER(SEARCH("m", GZ15:HG15)))) | HI15: =IF(COUNTA(GZ15:HG15)=0, "", COUNTA(GZ15:HG15) - SUMPRODUCT(--ISNUMBER(SEARCH("m", GZ15:HG15)))) | HT15: =IFERROR(ROUND(AVERAGE(HJ15,HL15,HN15,HP15,HR15), 2), "") | IC15: =IF(COUNTA(HU15:IB15)=0, "", SUMPRODUCT(--ISNUMBER(SEARCH("m", HU15:IB15)))) | ID15: =IF(COUNTA(HU15:IB15)=0, "", COUNTA(HU15:IB15) - SUMPRODUCT(--ISNUMBER(SEARCH("m", HU15:IB15)))) | IO15: =IFERROR(ROUND(AVERAGE(IE15,IG15,II15,IK15,IM15), 2), "") | IX15: =IF(COUNTA(IP15:IW15)=0, "", SUMPRODUCT(--ISNUMBER(SEARCH("m", IP15:IW15)))) | IY15: =IF(COUNTA(IP15:IW15)=0, "", COUNTA(IP15:IW15) - SUMPRODUCT(--ISNUMBER(SEARCH("m", IP15:IW15)))) | JJ15: =IFERROR(ROUND(AVERAGE(IZ15,JB15,JD15,JF15,JH15), 2), "") | JS15: =IF(COUNTA(JK15:JR15)=0, "", SUMPRODUCT(--ISNUMBER(SEARCH("m", JK15:JR15)))) | JT15: =IF(COUNTA(JK15:JR15)=0, "", COUNTA(JK15:JR15) - SUMPRODUCT(--ISNUMBER(SEARCH("m", JK15:JR15)))) | KE15: =IFERROR(ROUND(AVERAGE(JU15,JW15,JY15,KA15,KC15), 2), "") | KN15: =IF(COUNTA(KF15:KM15)=0, "", SUMPRODUCT(--ISNUMBER(SEARCH("m", KF15:KM15)))) | KO15: =IF(COUNTA(KF15:KM15)=0, "", COUNTA(KF15:KM15) - SUMPRODUCT(--ISNUMBER(SEARCH("m", KF15:KM15))))
A16: 8 | B16: DEMETER D.C. DENIS RĂZVAN | C16: 20 | D16: 126/83 | E16: =IFERROR(ROUND(AVERAGE(R16,AM16,BH16,CC16,CX16,DS16,EN16,FI16,GD16,GY16,HT16,IO16,JJ16,KE16), 2), "") | F16: =IF(SUM(AB16,AW16,BR16,CM16,DH16,EC16,EX16,FS16,GN16,HI16,ID16,IY16,JT16,KO16)=0, "", SUM(AB16,AW16,BR16,CM16,DH16,EC16,EX16,FS16,GN16,HI16,ID16,IY16,JT16,KO16)) | G16: =IF(SUM(AA16,AV16,BQ16,CL16,DG16,EB16,EW16,FR16,GM16,HH16,IC16,IX16,JS16,KN16)=0, "", SUM(AA16,AV16,BQ16,CL16,DG16,EB16,EW16,FR16,GM16,HH16,IC16,IX16,JS16,KN16)) | R16: =IFERROR(ROUND(AVERAGE(H16,J16,L16,N16,P16), 2), "") | AA16: =IF(COUNTA(S16:Z16)=0, "", SUMPRODUCT(--ISNUMBER(SEARCH("m", S16:Z16)))) | AB16: =IF(COUNTA(S16:Z16)=0, "", COUNTA(S16:Z16) - SUMPRODUCT(--ISNUMBER(SEARCH("m", S16:Z16)))) | AM16: =IFERROR(ROUND(AVERAGE(AC16,AE16,AG16,AI16,AK16), 2), "") | AV16: =IF(COUNTA(AN16:AU16)=0, "", SUMPRODUCT(--ISNUMBER(SEARCH("m", AN16:AU16)))) | AW16: =IF(COUNTA(AN16:AU16)=0, "", COUNTA(AN16:AU16) - SUMPRODUCT(--ISNUMBER(SEARCH("m", AN16:AU16)))) | BH16: =IFERROR(ROUND(AVERAGE(AX16,AZ16,BB16,BD16,BF16), 2), "") | BQ16: =IF(COUNTA(BI16:BP16)=0, "", SUMPRODUCT(--ISNUMBER(SEARCH("m", BI16:BP16)))) | BR16: =IF(COUNTA(BI16:BP16)=0, "", COUNTA(BI16:BP16) - SUMPRODUCT(--ISNUMBER(SEARCH("m", BI16:BP16)))) | CC16: =IFERROR(ROUND(AVERAGE(BS16,BU16,BW16,BY16,CA16), 2), "") | CL16: =IF(COUNTA(CD16:CK16)=0, "", SUMPRODUCT(--ISNUMBER(SEARCH("m", CD16:CK16)))) | CM16: =IF(COUNTA(CD16:CK16)=0, "", COUNTA(CD16:CK16) - SUMPRODUCT(--ISNUMBER(SEARCH("m", CD16:CK16)))) | CX16: =IFERROR(ROUND(AVERAGE(CN16,CP16,CR16,CT16,CV16), 2), "") | DG16: =IF(COUNTA(CY16:DF16)=0, "", SUMPRODUCT(--ISNUMBER(SEARCH("m", CY16:DF16)))) | DH16: =IF(COUNTA(CY16:DF16)=0, "", COUNTA(CY16:DF16) - SUMPRODUCT(--ISNUMBER(SEARCH("m", CY16:DF16)))) | DS16: =IFERROR(ROUND(AVERAGE(DI16,DK16,DM16,DO16,DQ16), 2), "") | EB16: =IF(COUNTA(DT16:EA16)=0, "", SUMPRODUCT(--ISNUMBER(SEARCH("m", DT16:EA16)))) | EC16: =IF(COUNTA(DT16:EA16)=0, "", COUNTA(DT16:EA16) - SUMPRODUCT(--ISNUMBER(SEARCH("m", DT16:EA16)))) | EN16: =IFERROR(ROUND(AVERAGE(ED16,EF16,EH16,EJ16,EL16), 2), "") | EW16: =IF(COUNTA(EO16:EV16)=0, "", SUMPRODUCT(--ISNUMBER(SEARCH("m", EO16:EV16)))) | EX16: =IF(COUNTA(EO16:EV16)=0, "", COUNTA(EO16:EV16) - SUMPRODUCT(--ISNUMBER(SEARCH("m", EO16:EV16)))) | FI16: =IFERROR(ROUND(AVERAGE(EY16,FA16,FC16,FE16,FG16), 2), "") | FR16: =IF(COUNTA(FJ16:FQ16)=0, "", SUMPRODUCT(--ISNUMBER(SEARCH("m", FJ16:FQ16)))) | FS16: =IF(COUNTA(FJ16:FQ16)=0, "", COUNTA(FJ16:FQ16) - SUMPRODUCT(--ISNUMBER(SEARCH("m", FJ16:FQ16)))) | GD16: =IFERROR(ROUND(AVERAGE(FT16,FV16,FX16,FZ16,GB16), 2), "") | GM16: =IF(COUNTA(GE16:GL16)=0, "", SUMPRODUCT(--ISNUMBER(SEARCH("m", GE16:GL16)))) | GN16: =IF(COUNTA(GE16:GL16)=0, "", COUNTA(GE16:GL16) - SUMPRODUCT(--ISNUMBER(SEARCH("m", GE16:GL16)))) | GY16: =IFERROR(ROUND(AVERAGE(GO16,GQ16,GS16,GU16,GW16), 2), "") | HH16: =IF(COUNTA(GZ16:HG16)=0, "", SUMPRODUCT(--ISNUMBER(SEARCH("m", GZ16:HG16)))) | HI16: =IF(COUNTA(GZ16:HG16)=0, "", COUNTA(GZ16:HG16) - SUMPRODUCT(--ISNUMBER(SEARCH("m", GZ16:HG16)))) | HT16: =IFERROR(ROUND(AVERAGE(HJ16,HL16,HN16,HP16,HR16), 2), "") | IC16: =IF(COUNTA(HU16:IB16)=0, "", SUMPRODUCT(--ISNUMBER(SEARCH("m", HU16:IB16)))) | ID16: =IF(COUNTA(HU16:IB16)=0, "", COUNTA(HU16:IB16) - SUMPRODUCT(--ISNUMBER(SEARCH("m", HU16:IB16)))) | IO16: =IFERROR(ROUND(AVERAGE(IE16,IG16,II16,IK16,IM16), 2), "") | IX16: =IF(COUNTA(IP16:IW16)=0, "", SUMPRODUCT(--ISNUMBER(SEARCH("m", IP16:IW16)))) | IY16: =IF(COUNTA(IP16:IW16)=0, "", COUNTA(IP16:IW16) - SUMPRODUCT(--ISNUMBER(SEARCH("m", IP16:IW16)))) | JJ16: =IFERROR(ROUND(AVERAGE(IZ16,JB16,JD16,JF16,JH16), 2), "") | JS16: =IF(COUNTA(JK16:JR16)=0, "", SUMPRODUCT(--ISNUMBER(SEARCH("m", JK16:JR16)))) | JT16: =IF(COUNTA(JK16:JR16)=0, "", COUNTA(JK16:JR16) - SUMPRODUCT(--ISNUMBER(SEARCH("m", JK16:JR16)))) | KE16: =IFERROR(ROUND(AVERAGE(JU16,JW16,JY16,KA16,KC16), 2), "") | KN16: =IF(COUNTA(KF16:KM16)=0, "", SUMPRODUCT(--ISNUMBER(SEARCH("m", KF16:KM16)))) | KO16: =IF(COUNTA(KF16:KM16)=0, "", COUNTA(KF16:KM16) - SUMPRODUCT(--ISNUMBER(SEARCH("m", KF16:KM16))))
A17: 9 | B17: FERENCZI E.C. MEDEA MARICARMEN | C17: 21 | D17: 126/84 | E17: =IFERROR(ROUND(AVERAGE(R17,AM17,BH17,CC17,CX17,DS17,EN17,FI17,GD17,GY17,HT17,IO17,JJ17,KE17), 2), "") | F17: =IF(SUM(AB17,AW17,BR17,CM17,DH17,EC17,EX17,FS17,GN17,HI17,ID17,IY17,JT17,KO17)=0, "", SUM(AB17,AW17,BR17,CM17,DH17,EC17,EX17,FS17,GN17,HI17,ID17,IY17,JT17,KO17)) | G17: =IF(SUM(AA17,AV17,BQ17,CL17,DG17,EB17,EW17,FR17,GM17,HH17,IC17,IX17,JS17,KN17)=0, "", SUM(AA17,AV17,BQ17,CL17,DG17,EB17,EW17,FR17,GM17,HH17,IC17,IX17,JS17,KN17)) | R17: =IFERROR(ROUND(AVERAGE(H17,J17,L17,N17,P17), 2), "") | AA17: =IF(COUNTA(S17:Z17)=0, "", SUMPRODUCT(--ISNUMBER(SEARCH("m", S17:Z17)))) | AB17: =IF(COUNTA(S17:Z17)=0, "", COUNTA(S17:Z17) - SUMPRODUCT(--ISNUMBER(SEARCH("m", S17:Z17)))) | AM17: =IFERROR(ROUND(AVERAGE(AC17,AE17,AG17,AI17,AK17), 2), "") | AV17: =IF(COUNTA(AN17:AU17)=0, "", SUMPRODUCT(--ISNUMBER(SEARCH("m", AN17:AU17)))) | AW17: =IF(COUNTA(AN17:AU17)=0, "", COUNTA(AN17:AU17) - SUMPRODUCT(--ISNUMBER(SEARCH("m", AN17:AU17)))) | BH17: =IFERROR(ROUND(AVERAGE(AX17,AZ17,BB17,BD17,BF17), 2), "") | BQ17: =IF(COUNTA(BI17:BP17)=0, "", SUMPRODUCT(--ISNUMBER(SEARCH("m", BI17:BP17)))) | BR17: =IF(COUNTA(BI17:BP17)=0, "", COUNTA(BI17:BP17) - SUMPRODUCT(--ISNUMBER(SEARCH("m", BI17:BP17)))) | CC17: =IFERROR(ROUND(AVERAGE(BS17,BU17,BW17,BY17,CA17), 2), "") | CL17: =IF(COUNTA(CD17:CK17)=0, "", SUMPRODUCT(--ISNUMBER(SEARCH("m", CD17:CK17)))) | CM17: =IF(COUNTA(CD17:CK17)=0, "", COUNTA(CD17:CK17) - SUMPRODUCT(--ISNUMBER(SEARCH("m", CD17:CK17)))) | CX17: =IFERROR(ROUND(AVERAGE(CN17,CP17,CR17,CT17,CV17), 2), "") | DG17: =IF(COUNTA(CY17:DF17)=0, "", SUMPRODUCT(--ISNUMBER(SEARCH("m", CY17:DF17)))) | DH17: =IF(COUNTA(CY17:DF17)=0, "", COUNTA(CY17:DF17) - SUMPRODUCT(--ISNUMBER(SEARCH("m", CY17:DF17)))) | DS17: =IFERROR(ROUND(AVERAGE(DI17,DK17,DM17,DO17,DQ17), 2), "") | EB17: =IF(COUNTA(DT17:EA17)=0, "", SUMPRODUCT(--ISNUMBER(SEARCH("m", DT17:EA17)))) | EC17: =IF(COUNTA(DT17:EA17)=0, "", COUNTA(DT17:EA17) - SUMPRODUCT(--ISNUMBER(SEARCH("m", DT17:EA17)))) | EN17: =IFERROR(ROUND(AVERAGE(ED17,EF17,EH17,EJ17,EL17), 2), "") | EW17: =IF(COUNTA(EO17:EV17)=0, "", SUMPRODUCT(--ISNUMBER(SEARCH("m", EO17:EV17)))) | EX17: =IF(COUNTA(EO17:EV17)=0, "", COUNTA(EO17:EV17) - SUMPRODUCT(--ISNUMBER(SEARCH("m", EO17:EV17)))) | FI17: =IFERROR(ROUND(AVERAGE(EY17,FA17,FC17,FE17,FG17), 2), "") | FR17: =IF(COUNTA(FJ17:FQ17)=0, "", SUMPRODUCT(--ISNUMBER(SEARCH("m", FJ17:FQ17)))) | FS17: =IF(COUNTA(FJ17:FQ17)=0, "", COUNTA(FJ17:FQ17) - SUMPRODUCT(--ISNUMBER(SEARCH("m", FJ17:FQ17)))) | GD17: =IFERROR(ROUND(AVERAGE(FT17,FV17,FX17,FZ17,GB17), 2), "") | GM17: =IF(COUNTA(GE17:GL17)=0, "", SUMPRODUCT(--ISNUMBER(SEARCH("m", GE17:GL17)))) | GN17: =IF(COUNTA(GE17:GL17)=0, "", COUNTA(GE17:GL17) - SUMPRODUCT(--ISNUMBER(SEARCH("m", GE17:GL17)))) | GY17: =IFERROR(ROUND(AVERAGE(GO17,GQ17,GS17,GU17,GW17), 2), "") | HH17: =IF(COUNTA(GZ17:HG17)=0, "", SUMPRODUCT(--ISNUMBER(SEARCH("m", GZ17:HG17)))) | HI17: =IF(COUNTA(GZ17:HG17)=0, "", COUNTA(GZ17:HG17) - SUMPRODUCT(--ISNUMBER(SEARCH("m", GZ17:HG17)))) | HT17: =IFERROR(ROUND(AVERAGE(HJ17,HL17,HN17,HP17,HR17), 2), "") | IC17: =IF(COUNTA(HU17:IB17)=0, "", SUMPRODUCT(--ISNUMBER(SEARCH("m", HU17:IB17)))) | ID17: =IF(COUNTA(HU17:IB17)=0, "", COUNTA(HU17:IB17) - SUMPRODUCT(--ISNUMBER(SEARCH("m", HU17:IB17)))) | IO17: =IFERROR(ROUND(AVERAGE(IE17,IG17,II17,IK17,IM17), 2), "") | IX17: =IF(COUNTA(IP17:IW17)=0, "", SUMPRODUCT(--ISNUMBER(SEARCH("m", IP17:IW17)))) | IY17: =IF(COUNTA(IP17:IW17)=0, "", COUNTA(IP17:IW17) - SUMPRODUCT(--ISNUMBER(SEARCH("m", IP17:IW17)))) | JJ17: =IFERROR(ROUND(AVERAGE(IZ17,JB17,JD17,JF17,JH17), 2), "") | JS17: =IF(COUNTA(JK17:JR17)=0, "", SUMPRODUCT(--ISNUMBER(SEARCH("m", JK17:JR17)))) | JT17: =IF(COUNTA(JK17:JR17)=0, "", COUNTA(JK17:JR17) - SUMPRODUCT(--ISNUMBER(SEARCH("m", JK17:JR17)))) | KE17: =IFERROR(ROUND(AVERAGE(JU17,JW17,JY17,KA17,KC17), 2), "") | KN17: =IF(COUNTA(KF17:KM17)=0, "", SUMPRODUCT(--ISNUMBER(SEARCH("m", KF17:KM17)))) | KO17: =IF(COUNTA(KF17:KM17)=0, "", COUNTA(KF17:KM17) - SUMPRODUCT(--ISNUMBER(SEARCH("m", KF17:KM17))))
A18: 10 | B18: FLOREA V. FLAVIU CRISTIAN | C18: 22 | D18: 126/85 | E18: =IFERROR(ROUND(AVERAGE(R18,AM18,BH18,CC18,CX18,DS18,EN18,FI18,GD18,GY18,HT18,IO18,JJ18,KE18), 2), "") | F18: =IF(SUM(AB18,AW18,BR18,CM18,DH18,EC18,EX18,FS18,GN18,HI18,ID18,IY18,JT18,KO18)=0, "", SUM(AB18,AW18,BR18,CM18,DH18,EC18,EX18,FS18,GN18,HI18,ID18,IY18,JT18,KO18)) | G18: =IF(SUM(AA18,AV18,BQ18,CL18,DG18,EB18,EW18,FR18,GM18,HH18,IC18,IX18,JS18,KN18)=0, "", SUM(AA18,AV18,BQ18,CL18,DG18,EB18,EW18,FR18,GM18,HH18,IC18,IX18,JS18,KN18)) | R18: =IFERROR(ROUND(AVERAGE(H18,J18,L18,N18,P18), 2), "") | AA18: =IF(COUNTA(S18:Z18)=0, "", SUMPRODUCT(--ISNUMBER(SEARCH("m", S18:Z18)))) | AB18: =IF(COUNTA(S18:Z18)=0, "", COUNTA(S18:Z18) - SUMPRODUCT(--ISNUMBER(SEARCH("m", S18:Z18)))) | AM18: =IFERROR(ROUND(AVERAGE(AC18,AE18,AG18,AI18,AK18), 2), "") | AV18: =IF(COUNTA(AN18:AU18)=0, "", SUMPRODUCT(--ISNUMBER(SEARCH("m", AN18:AU18)))) | AW18: =IF(COUNTA(AN18:AU18)=0, "", COUNTA(AN18:AU18) - SUMPRODUCT(--ISNUMBER(SEARCH("m", AN18:AU18)))) | BH18: =IFERROR(ROUND(AVERAGE(AX18,AZ18,BB18,BD18,BF18), 2), "") | BQ18: =IF(COUNTA(BI18:BP18)=0, "", SUMPRODUCT(--ISNUMBER(SEARCH("m", BI18:BP18)))) | BR18: =IF(COUNTA(BI18:BP18)=0, "", COUNTA(BI18:BP18) - SUMPRODUCT(--ISNUMBER(SEARCH("m", BI18:BP18)))) | CC18: =IFERROR(ROUND(AVERAGE(BS18,BU18,BW18,BY18,CA18), 2), "") | CL18: =IF(COUNTA(CD18:CK18)=0, "", SUMPRODUCT(--ISNUMBER(SEARCH("m", CD18:CK18)))) | CM18: =IF(COUNTA(CD18:CK18)=0, "", COUNTA(CD18:CK18) - SUMPRODUCT(--ISNUMBER(SEARCH("m", CD18:CK18)))) | CX18: =IFERROR(ROUND(AVERAGE(CN18,CP18,CR18,CT18,CV18), 2), "") | DG18: =IF(COUNTA(CY18:DF18)=0, "", SUMPRODUCT(--ISNUMBER(SEARCH("m", CY18:DF18)))) | DH18: =IF(COUNTA(CY18:DF18)=0, "", COUNTA(CY18:DF18) - SUMPRODUCT(--ISNUMBER(SEARCH("m", CY18:DF18)))) | DS18: =IFERROR(ROUND(AVERAGE(DI18,DK18,DM18,DO18,DQ18), 2), "") | EB18: =IF(COUNTA(DT18:EA18)=0, "", SUMPRODUCT(--ISNUMBER(SEARCH("m", DT18:EA18)))) | EC18: =IF(COUNTA(DT18:EA18)=0, "", COUNTA(DT18:EA18) - SUMPRODUCT(--ISNUMBER(SEARCH("m", DT18:EA18)))) | EN18: =IFERROR(ROUND(AVERAGE(ED18,EF18,EH18,EJ18,EL18), 2), "") | EW18: =IF(COUNTA(EO18:EV18)=0, "", SUMPRODUCT(--ISNUMBER(SEARCH("m", EO18:EV18)))) | EX18: =IF(COUNTA(EO18:EV18)=0, "", COUNTA(EO18:EV18) - SUMPRODUCT(--ISNUMBER(SEARCH("m", EO18:EV18)))) | FI18: =IFERROR(ROUND(AVERAGE(EY18,FA18,FC18,FE18,FG18), 2), "") | FR18: =IF(COUNTA(FJ18:FQ18)=0, "", SUMPRODUCT(--ISNUMBER(SEARCH("m", FJ18:FQ18)))) | FS18: =IF(COUNTA(FJ18:FQ18)=0, "", COUNTA(FJ18:FQ18) - SUMPRODUCT(--ISNUMBER(SEARCH("m", FJ18:FQ18)))) | GD18: =IFERROR(ROUND(AVERAGE(FT18,FV18,FX18,FZ18,GB18), 2), "") | GM18: =IF(COUNTA(GE18:GL18)=0, "", SUMPRODUCT(--ISNUMBER(SEARCH("m", GE18:GL18)))) | GN18: =IF(COUNTA(GE18:GL18)=0, "", COUNTA(GE18:GL18) - SUMPRODUCT(--ISNUMBER(SEARCH("m", GE18:GL18)))) | GY18: =IFERROR(ROUND(AVERAGE(GO18,GQ18,GS18,GU18,GW18), 2), "") | HH18: =IF(COUNTA(GZ18:HG18)=0, "", SUMPRODUCT(--ISNUMBER(SEARCH("m", GZ18:HG18)))) | HI18: =IF(COUNTA(GZ18:HG18)=0, "", COUNTA(GZ18:HG18) - SUMPRODUCT(--ISNUMBER(SEARCH("m", GZ18:HG18)))) | HT18: =IFERROR(ROUND(AVERAGE(HJ18,HL18,HN18,HP18,HR18), 2), "") | IC18: =IF(COUNTA(HU18:IB18)=0, "", SUMPRODUCT(--ISNUMBER(SEARCH("m", HU18:IB18)))) | ID18: =IF(COUNTA(HU18:IB18)=0, "", COUNTA(HU18:IB18) - SUMPRODUCT(--ISNUMBER(SEARCH("m", HU18:IB18)))) | IO18: =IFERROR(ROUND(AVERAGE(IE18,IG18,II18,IK18,IM18), 2), "") | IX18: =IF(COUNTA(IP18:IW18)=0, "", SUMPRODUCT(--ISNUMBER(SEARCH("m", IP18:IW18)))) | IY18: =IF(COUNTA(IP18:IW18)=0, "", COUNTA(IP18:IW18) - SUMPRODUCT(--ISNUMBER(SEARCH("m", IP18:IW18)))) | JJ18: =IFERROR(ROUND(AVERAGE(IZ18,JB18,JD18,JF18,JH18), 2), "") | JS18: =IF(COUNTA(JK18:JR18)=0, "", SUMPRODUCT(--ISNUMBER(SEARCH("m", JK18:JR18)))) | JT18: =IF(COUNTA(JK18:JR18)=0, "", COUNTA(JK18:JR18) - SUMPRODUCT(--ISNUMBER(SEARCH("m", JK18:JR18)))) | KE18: =IFERROR(ROUND(AVERAGE(JU18,JW18,JY18,KA18,KC18), 2), "") | KN18: =IF(COUNTA(KF18:KM18)=0, "", SUMPRODUCT(--ISNUMBER(SEARCH("m", KF18:KM18)))) | KO18: =IF(COUNTA(KF18:KM18)=0, "", COUNTA(KF18:KM18) - SUMPRODUCT(--ISNUMBER(SEARCH("m", KF18:KM18))))
A19: 11 | B19: GHERMAN M.I. DAVID MARIUS | C19: 23 | D19: 126/86 | E19: =IFERROR(ROUND(AVERAGE(R19,AM19,BH19,CC19,CX19,DS19,EN19,FI19,GD19,GY19,HT19,IO19,JJ19,KE19), 2), "") | F19: =IF(SUM(AB19,AW19,BR19,CM19,DH19,EC19,EX19,FS19,GN19,HI19,ID19,IY19,JT19,KO19)=0, "", SUM(AB19,AW19,BR19,CM19,DH19,EC19,EX19,FS19,GN19,HI19,ID19,IY19,JT19,KO19)) | G19: =IF(SUM(AA19,AV19,BQ19,CL19,DG19,EB19,EW19,FR19,GM19,HH19,IC19,IX19,JS19,KN19)=0, "", SUM(AA19,AV19,BQ19,CL19,DG19,EB19,EW19,FR19,GM19,HH19,IC19,IX19,JS19,KN19)) | R19: =IFERROR(ROUND(AVERAGE(H19,J19,L19,N19,P19), 2), "") | AA19: =IF(COUNTA(S19:Z19)=0, "", SUMPRODUCT(--ISNUMBER(SEARCH("m", S19:Z19)))) | AB19: =IF(COUNTA(S19:Z19)=0, "", COUNTA(S19:Z19) - SUMPRODUCT(--ISNUMBER(SEARCH("m", S19:Z19)))) | AM19: =IFERROR(ROUND(AVERAGE(AC19,AE19,AG19,AI19,AK19), 2), "") | AV19: =IF(COUNTA(AN19:AU19)=0, "", SUMPRODUCT(--ISNUMBER(SEARCH("m", AN19:AU19)))) | AW19: =IF(COUNTA(AN19:AU19)=0, "", COUNTA(AN19:AU19) - SUMPRODUCT(--ISNUMBER(SEARCH("m", AN19:AU19)))) | BH19: =IFERROR(ROUND(AVERAGE(AX19,AZ19,BB19,BD19,BF19), 2), "") | BQ19: =IF(COUNTA(BI19:BP19)=0, "", SUMPRODUCT(--ISNUMBER(SEARCH("m", BI19:BP19)))) | BR19: =IF(COUNTA(BI19:BP19)=0, "", COUNTA(BI19:BP19) - SUMPRODUCT(--ISNUMBER(SEARCH("m", BI19:BP19)))) | CC19: =IFERROR(ROUND(AVERAGE(BS19,BU19,BW19,BY19,CA19), 2), "") | CL19: =IF(COUNTA(CD19:CK19)=0, "", SUMPRODUCT(--ISNUMBER(SEARCH("m", CD19:CK19)))) | CM19: =IF(COUNTA(CD19:CK19)=0, "", COUNTA(CD19:CK19) - SUMPRODUCT(--ISNUMBER(SEARCH("m", CD19:CK19)))) | CX19: =IFERROR(ROUND(AVERAGE(CN19,CP19,CR19,CT19,CV19), 2), "") | DG19: =IF(COUNTA(CY19:DF19)=0, "", SUMPRODUCT(--ISNUMBER(SEARCH("m", CY19:DF19)))) | DH19: =IF(COUNTA(CY19:DF19)=0, "", COUNTA(CY19:DF19) - SUMPRODUCT(--ISNUMBER(SEARCH("m", CY19:DF19)))) | DS19: =IFERROR(ROUND(AVERAGE(DI19,DK19,DM19,DO19,DQ19), 2), "") | EB19: =IF(COUNTA(DT19:EA19)=0, "", SUMPRODUCT(--ISNUMBER(SEARCH("m", DT19:EA19)))) | EC19: =IF(COUNTA(DT19:EA19)=0, "", COUNTA(DT19:EA19) - SUMPRODUCT(--ISNUMBER(SEARCH("m", DT19:EA19)))) | EN19: =IFERROR(ROUND(AVERAGE(ED19,EF19,EH19,EJ19,EL19), 2), "") | EW19: =IF(COUNTA(EO19:EV19)=0, "", SUMPRODUCT(--ISNUMBER(SEARCH("m", EO19:EV19)))) | EX19: =IF(COUNTA(EO19:EV19)=0, "", COUNTA(EO19:EV19) - SUMPRODUCT(--ISNUMBER(SEARCH("m", EO19:EV19)))) | FI19: =IFERROR(ROUND(AVERAGE(EY19,FA19,FC19,FE19,FG19), 2), "") | FR19: =IF(COUNTA(FJ19:FQ19)=0, "", SUMPRODUCT(--ISNUMBER(SEARCH("m", FJ19:FQ19)))) | FS19: =IF(COUNTA(FJ19:FQ19)=0, "", COUNTA(FJ19:FQ19) - SUMPRODUCT(--ISNUMBER(SEARCH("m", FJ19:FQ19)))) | GD19: =IFERROR(ROUND(AVERAGE(FT19,FV19,FX19,FZ19,GB19), 2), "") | GM19: =IF(COUNTA(GE19:GL19)=0, "", SUMPRODUCT(--ISNUMBER(SEARCH("m", GE19:GL19)))) | GN19: =IF(COUNTA(GE19:GL19)=0, "", COUNTA(GE19:GL19) - SUMPRODUCT(--ISNUMBER(SEARCH("m", GE19:GL19)))) | GY19: =IFERROR(ROUND(AVERAGE(GO19,GQ19,GS19,GU19,GW19), 2), "") | HH19: =IF(COUNTA(GZ19:HG19)=0, "", SUMPRODUCT(--ISNUMBER(SEARCH("m", GZ19:HG19)))) | HI19: =IF(COUNTA(GZ19:HG19)=0, "", COUNTA(GZ19:HG19) - SUMPRODUCT(--ISNUMBER(SEARCH("m", GZ19:HG19)))) | HT19: =IFERROR(ROUND(AVERAGE(HJ19,HL19,HN19,HP19,HR19), 2), "") | IC19: =IF(COUNTA(HU19:IB19)=0, "", SUMPRODUCT(--ISNUMBER(SEARCH("m", HU19:IB19)))) | ID19: =IF(COUNTA(HU19:IB19)=0, "", COUNTA(HU19:IB19) - SUMPRODUCT(--ISNUMBER(SEARCH("m", HU19:IB19)))) | IO19: =IFERROR(ROUND(AVERAGE(IE19,IG19,II19,IK19,IM19), 2), "") | IX19: =IF(COUNTA(IP19:IW19)=0, "", SUMPRODUCT(--ISNUMBER(SEARCH("m", IP19:IW19)))) | IY19: =IF(COUNTA(IP19:IW19)=0, "", COUNTA(IP19:IW19) - SUMPRODUCT(--ISNUMBER(SEARCH("m", IP19:IW19)))) | JJ19: =IFERROR(ROUND(AVERAGE(IZ19,JB19,JD19,JF19,JH19), 2), "") | JS19: =IF(COUNTA(JK19:JR19)=0, "", SUMPRODUCT(--ISNUMBER(SEARCH("m", JK19:JR19)))) | JT19: =IF(COUNTA(JK19:JR19)=0, "", COUNTA(JK19:JR19) - SUMPRODUCT(--ISNUMBER(SEARCH("m", JK19:JR19)))) | KE19: =IFERROR(ROUND(AVERAGE(JU19,JW19,JY19,KA19,KC19), 2), "") | KN19: =IF(COUNTA(KF19:KM19)=0, "", SUMPRODUCT(--ISNUMBER(SEARCH("m", KF19:KM19)))) | KO19: =IF(COUNTA(KF19:KM19)=0, "", COUNTA(KF19:KM19) - SUMPRODUCT(--ISNUMBER(SEARCH("m", KF19:KM19))))
